Workbook

Sheet COVER
B2: SISTEM PENDUKUNG KEPUTUSAN PENGADAAN PERANGKAT LAPTOP BERBASIS E-KATALOG MENGGUNAKAN METODE SIMPLE ADDITIVE WEIGHTING (SAW) PADA KEMENTERIAN PERDAGANGAN
B7: INFORMASI PENELITIAN
B8: Referensi Regulasi | C8: Kepmendag No. 2060 Tahun 2025
B9: Metode | C9: Simple Additive Weighting (SAW)
B10: Jumlah Alternatif | C10: 75 Laptop dari E-Katalog LKPP
B11: Jumlah Kriteria | C11: 5 Kriteria Evaluasi
B12: Sumber Data | C12: katalog.inaproc.id / e-Katalog LKPP
B13: Kriteria 1 (C1) | C13: Nilai TKDN (%), (Benefit), (Bobot 30%)
B14: Kriteria 2 (C2) | C14: Kapasitas RAM (GB) (Benefit), (Bobot 25%)
B15: Kriteria 3 (C3) | C15: Kapasitas SSD (GB) (Benefit), (Bobot 20%)
B16: Kriteria 4 (C4) | C16: Masa Garansi (Tahun) (Benefit), (Bobot 15%)
B17: Kriteria 5 (C5) | C17: Harga Satuan (Rp), (Cost), (Bobot 10%)

Sheet DATA ALTERNATIF
A1: DATA ALTERNATIF 75 LAPTOP
A2: Kriteria didukung dari Kepmendag No. 2060 Tahun 2025
A4: No | B4: Kode | C4: Nama Produk / Model | D4: Merek | E4: C1 TKDN + BMP (%) | F4: C2 RAM (GB) | G4: C3 SSD (GB) | H4: C4 Garansi (Thn) | I4: C5 Harga (Rp) | J4: LINK E KATALOG (TARO SINI YA GES LINKNYA)
A5: 1 | B5: A01 | C5: Lenovo IdeaPad Slim 3 15IAH8 | D5: Lenovo | E5: 41.5 | F5: 8 | G5: 512 | H5: 1 | I5: 13722375 | J5: https://katalog.inaproc.id/artajaya-borneo/lenovo-ideapad-slim-3
A6: 2 | B6: A02 | C6: Lenovo IdeaPad Slim 3 15IAN8 | D6: Lenovo | E6: 40 | F6: 16 | G6: 512 | H6: 1 | I6: 19846800 | J6: https://katalog.inaproc.id/sentral-baroena-jaya/lenovo-ideapad-slim-3
A7: 3 | B7: A03 | C7: Lenovo ThinkPad E14 Gen 5 | D7: Lenovo | E7: 38.2 | F7: 16 | G7: 512 | H7: 1 | I7: 14088731 | J7: https://katalog.inaproc.id/amins-project-teknologi-indonesia/lenovo-thinkpad-e14-gen-5-intel-core-i3-1315u-8gb-512gb-w11pro
A8: 4 | B8: A04 | C8: Lenovo ThinkPad L14 Gen 4 | D8: Lenovo | E8: 38.2 | F8: 8 | G8: 512 | H8: 3 | I8: 21000000 | J8: https://katalog.inaproc.id/ayooklik-pantero-tangara/lenovo-thinkpad-l14-gen-4-intel-21h10068id
A9: 5 | B9: A05 | C9: Lenovo ThinkBook 14 G6 IRL | D9: Lenovo | E9: 37.8 | F9: 8 | G9: 512 | H9: 2 | I9: 13900000 | J9: https://katalog.inaproc.id/pt-sinergi-dinamika-jaya/lenovo-thinkbook-14-g6-irl-21kg00byid
A10: 6 | B10: A06 | C10: ASUS Vivobook Go 14 E1404FA | D10: ASUS | E10: 44,45 | F10: 8 | G10: 512 | H10: 1 | I10: 14041500 | J10: https://katalog.inaproc.id/prada-noesantara-group/asus-vivobook-go-14-e1404fa
A11: 7 | B11: A07 | C11: ASUS Vivobook 14 A1404ZA | D11: ASUS | E11: 40.1 | F11: 8 | G11: 512 | H11: 1 | I11: 13150000 | J11: https://katalog.inaproc.id/qheyzee-sentosa-abadi/asus-vivobook-14-a1404za-vips5852m
A12: 8 | B12: A08 | C12: ASUS Vivobook 15 X1504ZA | D12: ASUS | E12: 40.1 | F12: 8 | G12: 512 | H12: 1 | I12: 11488500 | J12: https://katalog.inaproc.id/grafika-permai/asus-vivobook-15-x1504za-nj247-intel-core-i7
A13: 9 | B13: A09 | C13: ASUS ExpertBook B1 B1402CVA-NK7110X | D13: ASUS | E13: 41.3 | F13: 16 | G13: 1024 | H13: 3 | I13: 21959000 | J13: https://katalog.inaproc.id/pt-cantigi-solusi-nusantara/asus-expertbook-b1-b1402cva-nk7110x
A14: 10 | B14: A10 | C14: ASUS ExpertBook B1 B1402CVA | D14: ASUS | E14: 41.3 | F14: 16 | G14: 1024 | H14: 3 | I14: 22199000 | J14: https://katalog.inaproc.id/pt-cantigi-solusi-nusantara/asus-expertbook-b1-b1402cva-nk7111x
A15: 11 | B15: A11 | C15: ASUS ExpertBook B5 B5402CVA | D15: ASUS | E15: 41.3 | F15: 8 | G15: 512 | H15: 1 | I15: 25752000 | J15: https://katalog.inaproc.id/tiga-sejahtera/laptop-asus-expertbook-b5
A16: 12 | B16: A12 | C16: ASUS ExpertBook P1 P1403CVA | D16: ASUS | E16: 45,32 | F16: 8 | G16: 512 | H16: 2 | I16: 9967000 | J16: https://katalog.inaproc.id/prana-atma-nirmala/asus-expertbook-p1-p1403cva
A17: 13 | B17: A13 | C17: HP 14S EP0001TU/EP0002TU i5-1335U | D17: HP | E17: 42.88 | F17: 8 | G17: 512 | H17: 1 | I17: 10878000 | J17: https://katalog.inaproc.id/solusi-klik-suroboyo-mandiri/hp-14s-ep0001tu-ep0002tu
A18: 14 | B18: A14 | C18: HP 14S-DQ5567TU i3-1215U | D18: HP | E18: 42.88 | F18: 8 | G18: 512 | H18: 2 | I18: 9549000 | J18: https://katalog.inaproc.id/wizar-jaya-abadi/laptop-hp-14s-dq5567tu | K18: Ikut garansi normalnya HP
A19: 15 | B19: A15 | C19: HP 14S DQ5153TU i5-1235U | D19: HP | E19: 42.88 | F19: 8 | G19: 512 | H19: 1 | I19: 13492050 | J19: https://katalog.inaproc.id/gogona/hp-laptop-14s-dq5153tu | K19: Garansinya 6 bulan aja
A20: 16 | B20: A16 | C20: HP 14S DQ5152TU i5 1235U | D20: HP | E20: 42.88 | F20: 8 | G20: 512 | H20: 2 | I20: 11999100 | J20: https://katalog.inaproc.id/zalbi-cakra-mega/laptop-hp-14s-dq5152tu-core-i5-1235u-8gb-512ssd-14-fhd-ips-w11-ohs
A21: 17 | B21: A17 | C21: HP 14s DQ5000TU i5-1240P | D21: HP | E21: 42 | F21: 8 | G21: 512 | H21: 2 | I21: 14349999 | J21: https://katalog.inaproc.id/insan-utama/laptop-hp-14s-dq5000tu-i5-1240p-8gb-512gb-14fhd-ips-iris-xe-w11-ohs
A22: 18 | B22: A18 | C22: Acer TravelMate P214 Ryzen 5 PRO | D22: Acer | E22: 44.84 | F22: 8 | G22: 512 | H22: 1 | I22: 16000000 | J22: https://katalog.inaproc.id/starindo-mitra-distribusi/acer-travelmate-p214-ryzen-5-pro
A23: 19 | B23: A19 | C23: Acer TravelMate P214 Intel Core 5 120U | D23: Acer | E23: 45.39 | F23: 8 | G23: 512 | H23: 2 | I23: 16650000 | J23: https://katalog.inaproc.id/burhan-cl5u/acer-travelmate-p214-ultra-5
A24: 20 | B24: A20 | C24: Acer TravelMate P414 Core-i5-1240P | D24: Acer | E24: 44.67 | F24: 16 | G24: 512 | H24: 3 | I24: 22089000 | J24: https://katalog.inaproc.id/berlian-irama-perkasa/acer-travelmate-p414-core-i5-16-gb-512-gb
A25: 21 | B25: A21 | C25: Acer TravelMate P214 Core-i5-0041 | D25: Acer | E25: 45.27 | F25: 8 | G25: 512 | H25: 1 | I25: 16872000 | J25: https://katalog.inaproc.id/tunas-solusi-mandiri-svtx/acer-travelmate-p214-tmp214-0041-core-i5
A26: 22 | B26: A22 | C26: Acer Travelmate P414 i7-1260P 106986 | D26: Acer | E26: 28.88 | F26: 16 | G26: 1000 | H26: 1 | I26: 38694600 | J26: https://katalog.inaproc.id/braga-mitra-abadi/acer-travelmate-p414-tmp414-0002 | K26: Tidak ada garansi
A27: 23 | B27: A23 | C27: Acer Travelmate P414 Intel Core Ultra 7-155U | D27: Acer | E27: 43.75 | F27: 16 | G27: 1024 | H27: 3 | I27: 49284000 | J27: https://katalog.inaproc.id/mahakarya-cipta-solusi/laptop-acer-travelmate-p414
A28: 24 | B28: A24 | C28: Acer Travelmate P214 i5 82022 | D28: Acer | E28: 26.55 | F28: 8 | G28: 512 | H28: 1 | I28: 11988000 | J28: https://katalog.inaproc.id/robby-future-multi/laptop-acer-travelmate | K28: bmp emang gaada
A29: 25 | B29: A25 | C29: Acer Travelmate P214 i5-1334U | D29: Acer | E29: 44.08 | F29: 8 | G29: 512 | H29: 3 | I29: 19250000 | J29: https://katalog.inaproc.id/astana-swastika/laptop-acer-travelmate-p214 | K29: garansinya resmi acer
A30: 26 | B30: A26 | C30: Acer Travelmate P214 i7-1355U | D30: Acer | E30: 44 | F30: 8 | G30: 512 | H30: 1 | I30: 14985000 | J30: https://katalog.inaproc.id/lesmana-jaya/laptop-acer-travelmate-p214
A31: 27 | B31: A27 | C31: Acer TravelMate P214 TMP214/0034 | D31: Acer | E31: 41.55 | F31: 8 | G31: 512 | H31: 3 | I31: 16650000 | J31: https://katalog.inaproc.id/bina-karya-jaya/laptop-acer-travelmate-p214 | K31: garansinya resmi acer
A32: 28 | B32: A28 | C32: Acer TravelMate P2 Core i3 | D32: Acer | E32: 44.22 | F32: 8 | G32: 512 | H32: 1 | I32: 12232200 | J32: https://katalog.inaproc.id/patriot-global-nusantara/laptop-acer-travelmate-p2-core-i3
A33: 29 | B33: A29 | C33: Acer Travelmate i5-1235U | D33: Acer | E33: 44.08 | F33: 8 | G33: 512 | H33: 1 | I33: 19758000 | J33: https://katalog.inaproc.id/nusa-bayangkara/laptop-acer-travelmate
A34: 30 | B34: A30 | C34: Acer Travelmate i5-1135G7 | D34: Acer | E34: 44.08 | F34: 8 | G34: 512 | H34: 1 | I34: 11182000 | J34: https://katalog.inaproc.id/bintang-prima-duta/laptop-acer-travelmate-i5 | K34: garansinya optional eh
A35: 31 | B35: A31 | C35: Acer TravelMate P2 TMP214 54 | D35: Acer | E35: 44.08 | F35: 16 | G35: 512 | H35: 1 | I35: 15424203 | J35: https://katalog.inaproc.id/tri-faeyza-mandiri/laptop-acer-travelmate-p2-tmp214-54-intel-core-i5-1235u-ram-16gb-512gb-ssd-nvme-windows-11
A36: 32 | B36: A32 | C36: Acer TravelMate P2 TMP214-54-5816 | D36: Acer | E36: 41.55 | F36: 16 | G36: 512 | H36: 1 | I36: 15151500 | J36: https://katalog.inaproc.id/trilateral-dinamika/acer-travelmate-p2-tmp214-54-5816-intel-i5-gen12-ram-16gb-ssd-512gb-tkdn
A37: 33 | B37: A33 | C37: Acer Travelmate P214 | D37: Acer | E37: 44.22 | F37: 8 | G37: 512 | H37: 2 | I37: 13500000 | J37: https://katalog.inaproc.id/yudi-santoso-bh3q/laptop-acer-travelmate-p214 | K37: garansi 1-2 tahun eh
A38: 34 | B38: A34 | C38: Acer TravelMate P214 i7-1165G7 | D38: Acer | E38: 41.55 | F38: 8 | G38: 512 | H38: 2 | I38: 19999000 | J38: https://katalog.inaproc.id/rejeki-aneka-sejahtera/laptop-acer-travelmate-p214
A39: 35 | B39: A35 | C39: Acer Travelmate P414 i7-1260P | D39: Acer | E39: 43.75 | F39: 16 | G39: 1024 | H39: 3 | I39: 31635000 | J39: https://katalog.inaproc.id/wisanggeni/laptop-acer-travelmate-p414
A40: 36 | B40: A36 | C40: Axioo Mybook | D40: Axioo | E40: 45.1 | F40: 8 | G40: 256 | H40: 1 | I40: 8796750 | J40: https://katalog.inaproc.id/karya-mandiri-axsd/axioo-mybook
A41: 37 | B41: A37 | C41: Axioo Mybook Prime E7 (16N5-3) | D41: Axioo | E41: 43.49 | F41: 16 | G41: 512 | H41: 1 | I41: 17900001 | J41: https://katalog.inaproc.id/cempaka-sinergy-bersama/axioo-mybook-prime-e7-16n5-3
...

Sheet BOBOT & KRITERIA
A1: KRITERIA, BOBOT, DAN TABEL KEANGGOTAAN FUZZY – METODE SAW
A3: KRITERIA DAN BOBOT PENILAIAN
A4: No | B4: Kode | C4: Nama Kriteria | D4: Jenis | E4: Bobot | F4: Bobot (%) | G4: Dasar Referensi
A5: 1 | B5: C1 | C5: Nilai TKDN + BMP (%) | D5: Benefit | E5: 0.3 | F5: 30 | G5: Kepmendag 2060/2025 – Min. TKDN 25%, BMP 40%
A6: 2 | B6: C2 | C6: Kapasitas RAM (GB) | D6: Benefit | E6: 0.25 | F6: 25 | G6: Kepmendag 2060/2025 – Spek Min RAM: 8 GB
A7: 3 | B7: C3 | C7: Kapasitas SSD (GB) | D7: Benefit | E7: 0.2 | F7: 20 | G7: Kepmendag 2060/2025 – Spek Min SSD: 256 GB
A8: 4 | B8: C4 | C8: Masa Garansi (Thn) | D8: Benefit | E8: 0.15 | F8: 15 | G8: Kepmendag 2060/2025 – Garansi minimal 1 tahun
A9: 5 | B9: C5 | C9: Harga Satuan (Rp) | D9: Cost | E9: 0.1 | F9: 10 | G9: Efisiensi anggaran TIK (Diktum Ketiga dan Keempat)
A10: TOTAL BOBOT | E10: 1 | F10: 100
A12: RUMUS SAW: Benefit → r_ij = f_ij / MAX(f_ij) | Cost → r_ij = MIN(f_ij) / f_ij | V_i = Σ (W_j × r_ij)
A14: TABEL FUZZY SETIAP KRITERIA
A16: BENEFIT | E16: BENEFIT
A17: No | B17: Nilai TKDN + BMP (%) | C17: Nilai Fuzzy | E17: No | F17: Kapasitas RAM (GB) | G17: Nilai Fuzzy
A18: 1 | B18: TKDN < 45% | C18: 0.25 | E18: 1 | F18: RAM = 8 GB | G18: 0.25
A19: 2 | B19: 45% ≤ TKDN < 50% | C19: 0.5 | E19: 2 | F19: RAM = 16 GB | G19: 0.5
A20: 3 | B20: 50% ≤ TKDN < 55% | C20: 0.75 | E20: 3 | F20: RAM = 32 GB | G20: 0.75
A21: 4 | B21: TKDN ≥ 55% | C21: 1 | E21: 4 | F21: RAM > 32 GB | G21: 1
A24: BENEFIT | E24: BENEFIT
A25: No | B25: Kapasitas SSD (GB) | C25: Nilai Fuzzy | E25: No | F25: Masa Garansi (Tahun) | G25: Nilai Fuzzy
A26: 1 | B26: SSD = 256 GB | C26: 0.33 | E26: 1 | F26: Garansi = 1 Tahun | G26: 0.25
A27: 2 | B27: SSD = 512 GB | C27: 0.67 | E27: 2 | F27: Garansi = 2 Tahun | G27: 0.5
A28: 3 | B28: SSD ≥ 1024 GB (1 TB) | C28: 1 | E28: 3 | F28: Garansi = 3 Tahun | G28: 0.75
E29: 4 | F29: Garansi > 3 Tahun | G29: 1
A31: COST
A32: No | B32: Harga Satuan (Rp) | C32: Nilai Fuzzy
A33: 1 | B33: Harga ≤ Rp 11.000.000 | C33: 0.25
A34: 2 | B34: Rp 11 jt < Harga ≤ Rp 14 jt | C34: 0.5
A35: 3 | B35: Rp 14 jt < Harga ≤ Rp 17 jt | C35: 0.75
A36: 4 | B36: Harga > Rp 17.000.000 | C36: 1

Sheet MATRIKS KEPUTUSAN
A1: MATRIKS KEPUTUSAN (X) – DATA MENTAH SETIAP ALTERNATIF DAN KRITERIA
A2: No | B2: Kode | C2: Nama Produk / Model | D2: C1 TKDN + BMP (%) | E2: C2 RAM (GB) | F2: C3 SSD (GB) | G2: C4 Garansi (Thn) | H2: C5 Harga (Rp)
A3: ='DATA ALTERNATIF'!A5 -> 1 | B3: ='DATA ALTERNATIF'!B5 -> A01 | C3: ='DATA ALTERNATIF'!C5 -> Lenovo IdeaPad Slim 3 15IAH8 | D3: ='DATA ALTERNATIF'!E5 -> 41.5 | E3: ='DATA ALTERNATIF'!F5 -> 8 | F3: ='DATA ALTERNATIF'!G5 -> 512 | G3: ='DATA ALTERNATIF'!H5 -> 1 | H3: ='DATA ALTERNATIF'!I5 -> 13722375
A4: ='DATA ALTERNATIF'!A6 -> 2 | B4: ='DATA ALTERNATIF'!B6 -> A02 | C4: ='DATA ALTERNATIF'!C6 -> Lenovo IdeaPad Slim 3 15IAN8 | D4: ='DATA ALTERNATIF'!E6 -> 40 | E4: ='DATA ALTERNATIF'!F6 -> 16 | F4: ='DATA ALTERNATIF'!G6 -> 512 | G4: ='DATA ALTERNATIF'!H6 -> 1 | H4: ='DATA ALTERNATIF'!I6 -> 19846800
A5: ='DATA ALTERNATIF'!A7 -> 3 | B5: ='DATA ALTERNATIF'!B7 -> A03 | C5: ='DATA ALTERNATIF'!C7 -> Lenovo ThinkPad E14 Gen 5 | D5: ='DATA ALTERNATIF'!E7 -> 38.2 | E5: ='DATA ALTERNATIF'!F7 -> 16 | F5: ='DATA ALTERNATIF'!G7 -> 512 | G5: ='DATA ALTERNATIF'!H7 -> 1 | H5: ='DATA ALTERNATIF'!I7 -> 14088731
A6: ='DATA ALTERNATIF'!A8 -> 4 | B6: ='DATA ALTERNATIF'!B8 -> A04 | C6: ='DATA ALTERNATIF'!C8 -> Lenovo ThinkPad L14 Gen 4 | D6: ='DATA ALTERNATIF'!E8 -> 38.2 | E6: ='DATA ALTERNATIF'!F8 -> 8 | F6: ='DATA ALTERNATIF'!G8 -> 512 | G6: ='DATA ALTERNATIF'!H8 -> 3 | H6: ='DATA ALTERNATIF'!I8 -> 21000000
A7: ='DATA ALTERNATIF'!A9 -> 5 | B7: ='DATA ALTERNATIF'!B9 -> A05 | C7: ='DATA ALTERNATIF'!C9 -> Lenovo ThinkBook 14 G6 IRL | D7: ='DATA ALTERNATIF'!E9 -> 37.8 | E7: ='DATA ALTERNATIF'!F9 -> 8 | F7: ='DATA ALTERNATIF'!G9 -> 512 | G7: ='DATA ALTERNATIF'!H9 -> 2 | H7: ='DATA ALTERNATIF'!I9 -> 13900000
A8: ='DATA ALTERNATIF'!A10 -> 6 | B8: ='DATA ALTERNATIF'!B10 -> A06 | C8: ='DATA ALTERNATIF'!C10 -> ASUS Vivobook Go 14 E1404FA | D8: ='DATA ALTERNATIF'!E10 -> 44,45 | E8: ='DATA ALTERNATIF'!F10 -> 8 | F8: ='DATA ALTERNATIF'!G10 -> 512 | G8: ='DATA ALTERNATIF'!H10 -> 1 | H8: ='DATA ALTERNATIF'!I10 -> 14041500
A9: ='DATA ALTERNATIF'!A11 -> 7 | B9: ='DATA ALTERNATIF'!B11 -> A07 | C9: ='DATA ALTERNATIF'!C11 -> ASUS Vivobook 14 A1404ZA | D9: ='DATA ALTERNATIF'!E11 -> 40.1 | E9: ='DATA ALTERNATIF'!F11 -> 8 | F9: ='DATA ALTERNATIF'!G11 -> 512 | G9: ='DATA ALTERNATIF'!H11 -> 1 | H9: ='DATA ALTERNATIF'!I11 -> 13150000
A10: ='DATA ALTERNATIF'!A12 -> 8 | B10: ='DATA ALTERNATIF'!B12 -> A08 | C10: ='DATA ALTERNATIF'!C12 -> ASUS Vivobook 15 X1504ZA | D10: ='DATA ALTERNATIF'!E12 -> 40.1 | E10: ='DATA ALTERNATIF'!F12 -> 8 | F10: ='DATA ALTERNATIF'!G12 -> 512 | G10: ='DATA ALTERNATIF'!H12 -> 1 | H10: ='DATA ALTERNATIF'!I12 -> 11488500
A11: ='DATA ALTERNATIF'!A13 -> 9 | B11: ='DATA ALTERNATIF'!B13 -> A09 | C11: ='DATA ALTERNATIF'!C13 -> ASUS ExpertBook B1 B1402CVA-NK7110X | D11: ='DATA ALTERNATIF'!E13 -> 41.3 | E11: ='DATA ALTERNATIF'!F13 -> 16 | F11: ='DATA ALTERNATIF'!G13 -> 1024 | G11: ='DATA ALTERNATIF'!H13 -> 3 | H11: ='DATA ALTERNATIF'!I13 -> 21959000
A12: ='DATA ALTERNATIF'!A14 -> 10 | B12: ='DATA ALTERNATIF'!B14 -> A10 | C12: ='DATA ALTERNATIF'!C14 -> ASUS ExpertBook B1 B1402CVA | D12: ='DATA ALTERNATIF'!E14 -> 41.3 | E12: ='DATA ALTERNATIF'!F14 -> 16 | F12: ='DATA ALTERNATIF'!G14 -> 1024 | G12: ='DATA ALTERNATIF'!H14 -> 3 | H12: ='DATA ALTERNATIF'!I14 -> 22199000
A13: ='DATA ALTERNATIF'!A15 -> 11 | B13: ='DATA ALTERNATIF'!B15 -> A11 | C13: ='DATA ALTERNATIF'!C15 -> ASUS ExpertBook B5 B5402CVA | D13: ='DATA ALTERNATIF'!E15 -> 41.3 | E13: ='DATA ALTERNATIF'!F15 -> 8 | F13: ='DATA ALTERNATIF'!G15 -> 512 | G13: ='DATA ALTERNATIF'!H15 -> 1 | H13: ='DATA ALTERNATIF'!I15 -> 25752000
A14: ='DATA ALTERNATIF'!A16 -> 12 | B14: ='DATA ALTERNATIF'!B16 -> A12 | C14: ='DATA ALTERNATIF'!C16 -> ASUS ExpertBook P1 P1403CVA | D14: ='DATA ALTERNATIF'!E16 -> 45,32 | E14: ='DATA ALTERNATIF'!F16 -> 8 | F14: ='DATA ALTERNATIF'!G16 -> 512 | G14: ='DATA ALTERNATIF'!H16 -> 2 | H14: ='DATA ALTERNATIF'!I16 -> 9967000
... A77: ='DATA ALTERNATIF'!A79 -> 75 | B77: ='DATA ALTERNATIF'!B79 -> A75 | C77: ='DATA ALTERNATIF'!C79 -> Acer TravelMate P214 i3-1315U | D77: ='DATA ALTERNATIF'!E79 -> 44.22 | E77: ='DATA ALTERNATIF'!F79 -> 8 | F77: ='DATA ALTERNATIF'!G79 -> 512 | G77: ='DATA ALTERNATIF'!H79 -> 2 | H77: ='DATA ALTERNATIF'!I79 -> 14850000
A78: MAX (Benefit) / MIN (Cost) | D78: =MAX(D3:D77) -> 48.68 | E78: =MAX(E3:E77) -> 24 | F78: =MAX(F3:F77) -> 1024 | G78: =MAX(G3:G77) -> 3 | H78: =MIN(H3:H77) -> 4332000

Sheet NILAI FUZZY
A1: NILAI FUZZY (f_ij)
A2: ='MATRIKS KEPUTUSAN'!A3 -> 1 | B2: ='MATRIKS KEPUTUSAN'!B3 -> A01 | C2: ='MATRIKS KEPUTUSAN'!C3 -> Lenovo IdeaPad Slim 3 15IAH8 | D2: =IF('MATRIKS KEPUTUSAN'!D3<45,0.25,IF('MATRIKS KEPUTUSAN'!D3<50,0.5,IF('MATRIKS KEPUTUSAN'!D3<55,0.75,1))) -> 0.25 | E2: =IF('MATRIKS KEPUTUSAN'!E3<=8,0.25,IF('MATRIKS KEPUTUSAN'!E3<=16,0.5,IF('MATRIKS KEPUTUSAN'!E3<=32,0.75,1))) -> 0.25 | F2: =IF('MATRIKS KEPUTUSAN'!F3<=256,0.33,IF('MATRIKS KEPUTUSAN'!F3<=512,0.67,1)) -> 0.67 | G2: =IF('MATRIKS KEPUTUSAN'!G3<=1,0.25,IF('MATRIKS KEPUTUSAN'!G3<=2,0.5,IF('MATRIKS KEPUTUSAN'!G3<=3,0.75,1))) -> 0.25 | H2: =IF('MATRIKS KEPUTUSAN'!H3<=11000000,0.25,IF('MATRIKS KEPUTUSAN'!H3<=14000000,0.5,IF('MATRIKS KEPUTUSAN'!H3<=17000000,0.75,1))) -> 0.5
A3: ='MATRIKS KEPUTUSAN'!A4 -> 2 | B3: ='MATRIKS KEPUTUSAN'!B4 -> A02 | C3: ='MATRIKS KEPUTUSAN'!C4 -> Lenovo IdeaPad Slim 3 15IAN8 | D3: =IF('MATRIKS KEPUTUSAN'!D4<45,0.25,IF('MATRIKS KEPUTUSAN'!D4<50,0.5,IF('MATRIKS KEPUTUSAN'!D4<55,0.75,1))) -> 0.25 | E3: =IF('MATRIKS KEPUTUSAN'!E4<=8,0.25,IF('MATRIKS KEPUTUSAN'!E4<=16,0.5,IF('MATRIKS KEPUTUSAN'!E4<=32,0.75,1))) -> 0.5 | F3: =IF('MATRIKS KEPUTUSAN'!F4<=256,0.33,IF('MATRIKS KEPUTUSAN'!F4<=512,0.67,1)) -> 0.67 | G3: =IF('MATRIKS KEPUTUSAN'!G4<=1,0.25,IF('MATRIKS KEPUTUSAN'!G4<=2,0.5,IF('MATRIKS KEPUTUSAN'!G4<=3,0.75,1))) -> 0.25 | H3: =IF('MATRIKS KEPUTUSAN'!H4<=11000000,0.25,IF('MATRIKS KEPUTUSAN'!H4<=14000000,0.5,IF('MATRIKS KEPUTUSAN'!H4<=17000000,0.75,1))) -> 1
A4: ='MATRIKS KEPUTUSAN'!A5 -> 3 | B4: ='MATRIKS KEPUTUSAN'!B5 -> A03 | C4: ='MATRIKS KEPUTUSAN'!C5 -> Lenovo ThinkPad E14 Gen 5 | D4: =IF('MATRIKS KEPUTUSAN'!D5<45,0.25,IF('MATRIKS KEPUTUSAN'!D5<50,0.5,IF('MATRIKS KEPUTUSAN'!D5<55,0.75,1))) -> 0.25 | E4: =IF('MATRIKS KEPUTUSAN'!E5<=8,0.25,IF('MATRIKS KEPUTUSAN'!E5<=16,0.5,IF('MATRIKS KEPUTUSAN'!E5<=32,0.75,1))) -> 0.5 | F4: =IF('MATRIKS KEPUTUSAN'!F5<=256,0.33,IF('MATRIKS KEPUTUSAN'!F5<=512,0.67,1)) -> 0.67 | G4: =IF('MATRIKS KEPUTUSAN'!G5<=1,0.25,IF('MATRIKS KEPUTUSAN'!G5<=2,0.5,IF('MATRIKS KEPUTUSAN'!G5<=3,0.75,1))) -> 0.25 | H4: =IF('MATRIKS KEPUTUSAN'!H5<=11000000,0.25,IF('MATRIKS KEPUTUSAN'!H5<=14000000,0.5,IF('MATRIKS KEPUTUSAN'!H5<=17000000,0.75,1))) -> 0.75
A5: ='MATRIKS KEPUTUSAN'!A6 -> 4 | B5: ='MATRIKS KEPUTUSAN'!B6 -> A04 | C5: ='MATRIKS KEPUTUSAN'!C6 -> Lenovo ThinkPad L14 Gen 4 | D5: =IF('MATRIKS KEPUTUSAN'!D6<45,0.25,IF('MATRIKS KEPUTUSAN'!D6<50,0.5,IF('MATRIKS KEPUTUSAN'!D6<55,0.75,1))) -> 0.25 | E5: =IF('MATRIKS KEPUTUSAN'!E6<=8,0.25,IF('MATRIKS KEPUTUSAN'!E6<=16,0.5,IF('MATRIKS KEPUTUSAN'!E6<=32,0.75,1))) -> 0.25 | F5: =IF('MATRIKS KEPUTUSAN'!F6<=256,0.33,IF('MATRIKS KEPUTUSAN'!F6<=512,0.67,1)) -> 0.67 | G5: =IF('MATRIKS KEPUTUSAN'!G6<=1,0.25,IF('MATRIKS KEPUTUSAN'!G6<=2,0.5,IF('MATRIKS KEPUTUSAN'!G6<=3,0.75,1))) -> 0.75 | H5: =IF('MATRIKS KEPUTUSAN'!H6<=11000000,0.25,IF('MATRIKS KEPUTUSAN'!H6<=14000000,0.5,IF('MATRIKS KEPUTUSAN'!H6<=17000000,0.75,1))) -> 1
A6: ='MATRIKS KEPUTUSAN'!A7 -> 5 | B6: ='MATRIKS KEPUTUSAN'!B7 -> A05 | C6: ='MATRIKS KEPUTUSAN'!C7 -> Lenovo ThinkBook 14 G6 IRL | D6: =IF('MATRIKS KEPUTUSAN'!D7<45,0.25,IF('MATRIKS KEPUTUSAN'!D7<50,0.5,IF('MATRIKS KEPUTUSAN'!D7<55,0.75,1))) -> 0.25 | E6: =IF('MATRIKS KEPUTUSAN'!E7<=8,0.25,IF('MATRIKS KEPUTUSAN'!E7<=16,0.5,IF('MATRIKS KEPUTUSAN'!E7<=32,0.75,1))) -> 0.25 | F6: =IF('MATRIKS KEPUTUSAN'!F7<=256,0.33,IF('MATRIKS KEPUTUSAN'!F7<=512,0.67,1)) -> 0.67 | G6: =IF('MATRIKS KEPUTUSAN'!G7<=1,0.25,IF('MATRIKS KEPUTUSAN'!G7<=2,0.5,IF('MATRIKS KEPUTUSAN'!G7<=3,0.75,1))) -> 0.5 | H6: =IF('MATRIKS KEPUTUSAN'!H7<=11000000,0.25,IF('MATRIKS KEPUTUSAN'!H7<=14000000,0.5,IF('MATRIKS KEPUTUSAN'!H7<=17000000,0.75,1))) -> 0.5
A7: ='MATRIKS KEPUTUSAN'!A8 -> 6 | B7: ='MATRIKS KEPUTUSAN'!B8 -> A06 | C7: ='MATRIKS KEPUTUSAN'!C8 -> ASUS Vivobook Go 14 E1404FA | D7: =IF('MATRIKS KEPUTUSAN'!D8<45,0.25,IF('MATRIKS KEPUTUSAN'!D8<50,0.5,IF('MATRIKS KEPUTUSAN'!D8<55,0.75,1))) -> 1 | E7: =IF('MATRIKS KEPUTUSAN'!E8<=8,0.25,IF('MATRIKS KEPUTUSAN'!E8<=16,0.5,IF('MATRIKS KEPUTUSAN'!E8<=32,0.75,1))) -> 0.25 | F7: =IF('MATRIKS KEPUTUSAN'!F8<=256,0.33,IF('MATRIKS KEPUTUSAN'!F8<=512,0.67,1)) -> 0.67 | G7: =IF('MATRIKS KEPUTUSAN'!G8<=1,0.25,IF('MATRIKS KEPUTUSAN'!G8<=2,0.5,IF('MATRIKS KEPUTUSAN'!G8<=3,0.75,1))) -> 0.25 | H7: =IF('MATRIKS KEPUTUSAN'!H8<=11000000,0.25,IF('MATRIKS KEPUTUSAN'!H8<=14000000,0.5,IF('MATRIKS KEPUTUSAN'!H8<=17000000,0.75,1))) -> 0.75
A8: ='MATRIKS KEPUTUSAN'!A9 -> 7 | B8: ='MATRIKS KEPUTUSAN'!B9 -> A07 | C8: ='MATRIKS KEPUTUSAN'!C9 -> ASUS Vivobook 14 A1404ZA | D8: =IF('MATRIKS KEPUTUSAN'!D9<45,0.25,IF('MATRIKS KEPUTUSAN'!D9<50,0.5,IF('MATRIKS KEPUTUSAN'!D9<55,0.75,1))) -> 0.25 | E8: =IF('MATRIKS KEPUTUSAN'!E9<=8,0.25,IF('MATRIKS KEPUTUSAN'!E9<=16,0.5,IF('MATRIKS KEPUTUSAN'!E9<=32,0.75,1))) -> 0.25 | F8: =IF('MATRIKS KEPUTUSAN'!F9<=256,0.33,IF('MATRIKS KEPUTUSAN'!F9<=512,0.67,1)) -> 0.67 | G8: =IF('MATRIKS KEPUTUSAN'!G9<=1,0.25,IF('MATRIKS KEPUTUSAN'!G9<=2,0.5,IF('MATRIKS KEPUTUSAN'!G9<=3,0.75,1))) -> 0.25 | H8: =IF('MATRIKS KEPUTUSAN'!H9<=11000000,0.25,IF('MATRIKS KEPUTUSAN'!H9<=14000000,0.5,IF('MATRIKS KEPUTUSAN'!H9<=17000000,0.75,1))) -> 0.5
A9: ='MATRIKS KEPUTUSAN'!A10 -> 8 | B9: ='MATRIKS KEPUTUSAN'!B10 -> A08 | C9: ='MATRIKS KEPUTUSAN'!C10 -> ASUS Vivobook 15 X1504ZA | D9: =IF('MATRIKS KEPUTUSAN'!D10<45,0.25,IF('MATRIKS KEPUTUSAN'!D10<50,0.5,IF('MATRIKS KEPUTUSAN'!D10<55,0.75,1))) -> 0.25 | E9: =IF('MATRIKS KEPUTUSAN'!E10<=8,0.25,IF('MATRIKS KEPUTUSAN'!E10<=16,0.5,IF('MATRIKS KEPUTUSAN'!E10<=32,0.75,1))) -> 0.25 | F9: =IF('MATRIKS KEPUTUSAN'!F10<=256,0.33,IF('MATRIKS KEPUTUSAN'!F10<=512,0.67,1)) -> 0.67 | G9: =IF('MATRIKS KEPUTUSAN'!G10<=1,0.25,IF('MATRIKS KEPUTUSAN'!G10<=2,0.5,IF('MATRIKS KEPUTUSAN'!G10<=3,0.75,1))) -> 0.25 | H9: =IF('MATRIKS KEPUTUSAN'!H10<=11000000,0.25,IF('MATRIKS KEPUTUSAN'!H10<=14000000,0.5,IF('MATRIKS KEPUTUSAN'!H10<=17000000,0.75,1))) -> 0.5
A10: ='MATRIKS KEPUTUSAN'!A11 -> 9 | B10: ='MATRIKS KEPUTUSAN'!B11 -> A09 | C10: ='MATRIKS KEPUTUSAN'!C11 -> ASUS ExpertBook B1 B1402CVA-NK7110X | D10: =IF('MATRIKS KEPUTUSAN'!D11<45,0.25,IF('MATRIKS KEPUTUSAN'!D11<50,0.5,IF('MATRIKS KEPUTUSAN'!D11<55,0.75,1))) -> 0.25 | E10: =IF('MATRIKS KEPUTUSAN'!E11<=8,0.25,IF('MATRIKS KEPUTUSAN'!E11<=16,0.5,IF('MATRIKS KEPUTUSAN'!E11<=32,0.75,1))) -> 0.5 | F10: =IF('MATRIKS KEPUTUSAN'!F11<=256,0.33,IF('MATRIKS KEPUTUSAN'!F11<=512,0.67,1)) -> 1 | G10: =IF('MATRIKS KEPUTUSAN'!G11<=1,0.25,IF('MATRIKS KEPUTUSAN'!G11<=2,0.5,IF('MATRIKS KEPUTUSAN'!G11<=3,0.75,1))) -> 0.75 | H10: =IF('MATRIKS KEPUTUSAN'!H11<=11000000,0.25,IF('MATRIKS KEPUTUSAN'!H11<=14000000,0.5,IF('MATRIKS KEPUTUSAN'!H11<=17000000,0.75,1))) -> 1
A11: ='MATRIKS KEPUTUSAN'!A12 -> 10 | B11: ='MATRIKS KEPUTUSAN'!B12 -> A10 | C11: ='MATRIKS KEPUTUSAN'!C12 -> ASUS ExpertBook B1 B1402CVA | D11: =IF('MATRIKS KEPUTUSAN'!D12<45,0.25,IF('MATRIKS KEPUTUSAN'!D12<50,0.5,IF('MATRIKS KEPUTUSAN'!D12<55,0.75,1))) -> 0.25 | E11: =IF('MATRIKS KEPUTUSAN'!E12<=8,0.25,IF('MATRIKS KEPUTUSAN'!E12<=16,0.5,IF('MATRIKS KEPUTUSAN'!E12<=32,0.75,1))) -> 0.5 | F11: =IF('MATRIKS KEPUTUSAN'!F12<=256,0.33,IF('MATRIKS KEPUTUSAN'!F12<=512,0.67,1)) -> 1 | G11: =IF('MATRIKS KEPUTUSAN'!G12<=1,0.25,IF('MATRIKS KEPUTUSAN'!G12<=2,0.5,IF('MATRIKS KEPUTUSAN'!G12<=3,0.75,1))) -> 0.75 | H11: =IF('MATRIKS KEPUTUSAN'!H12<=11000000,0.25,IF('MATRIKS KEPUTUSAN'!H12<=14000000,0.5,IF('MATRIKS KEPUTUSAN'!H12<=17000000,0.75,1))) -> 1
A12: ='MATRIKS KEPUTUSAN'!A13 -> 11 | B12: ='MATRIKS KEPUTUSAN'!B13 -> A11 | C12: ='MATRIKS KEPUTUSAN'!C13 -> ASUS ExpertBook B5 B5402CVA | D12: =IF('MATRIKS KEPUTUSAN'!D13<45,0.25,IF('MATRIKS KEPUTUSAN'!D13<50,0.5,IF('MATRIKS KEPUTUSAN'!D13<55,0.75,1))) -> 0.25 | E12: =IF('MATRIKS KEPUTUSAN'!E13<=8,0.25,IF('MATRIKS KEPUTUSAN'!E13<=16,0.5,IF('MATRIKS KEPUTUSAN'!E13<=32,0.75,1))) -> 0.25 | F12: =IF('MATRIKS KEPUTUSAN'!F13<=256,0.33,IF('MATRIKS KEPUTUSAN'!F13<=512,0.67,1)) -> 0.67 | G12: =IF('MATRIKS KEPUTUSAN'!G13<=1,0.25,IF('MATRIKS KEPUTUSAN'!G13<=2,0.5,IF('MATRIKS KEPUTUSAN'!G13<=3,0.75,1))) -> 0.25 | H12: =IF('MATRIKS KEPUTUSAN'!H13<=11000000,0.25,IF('MATRIKS KEPUTUSAN'!H13<=14000000,0.5,IF('MATRIKS KEPUTUSAN'!H13<=17000000,0.75,1))) -> 1
A13: ='MATRIKS KEPUTUSAN'!A14 -> 12 | B13: ='MATRIKS KEPUTUSAN'!B14 -> A12 | C13: ='MATRIKS KEPUTUSAN'!C14 -> ASUS ExpertBook P1 P1403CVA | D13: =IF('MATRIKS KEPUTUSAN'!D14<45,0.25,IF('MATRIKS KEPUTUSAN'!D14<50,0.5,IF('MATRIKS KEPUTUSAN'!D14<55,0.75,1))) -> 1 | E13: =IF('MATRIKS KEPUTUSAN'!E14<=8,0.25,IF('MATRIKS KEPUTUSAN'!E14<=16,0.5,IF('MATRIKS KEPUTUSAN'!E14<=32,0.75,1))) -> 0.25 | F13: =IF('MATRIKS KEPUTUSAN'!F14<=256,0.33,IF('MATRIKS KEPUTUSAN'!F14<=512,0.67,1)) -> 0.67 | G13: =IF('MATRIKS KEPUTUSAN'!G14<=1,0.25,IF('MATRIKS KEPUTUSAN'!G14<=2,0.5,IF('MATRIKS KEPUTUSAN'!G14<=3,0.75,1))) -> 0.5 | H13: =IF('MATRIKS KEPUTUSAN'!H14<=11000000,0.25,IF('MATRIKS KEPUTUSAN'!H14<=14000000,0.5,IF('MATRIKS KEPUTUSAN'!H14<=17000000,0.75,1))) -> 0.25
... A76: ='MATRIKS KEPUTUSAN'!A77 -> 75 | B76: ='MATRIKS KEPUTUSAN'!B77 -> A75 | C76: ='MATRIKS KEPUTUSAN'!C77 -> Acer TravelMate P214 i3-1315U | D76: =IF('MATRIKS KEPUTUSAN'!D77<45,0.25,IF('MATRIKS KEPUTUSAN'!D77<50,0.5,IF('MATRIKS KEPUTUSAN'!D77<55,0.75,1))) -> 0.25 | E76: =IF('MATRIKS KEPUTUSAN'!E77<=8,0.25,IF('MATRIKS KEPUTUSAN'!E77<=16,0.5,IF('MATRIKS KEPUTUSAN'!E77<=32,0.75,1))) -> 0.25 | F76: =IF('MATRIKS KEPUTUSAN'!F77<=256,0.33,IF('MATRIKS KEPUTUSAN'!F77<=512,0.67,1)) -> 0.67 | G76: =IF('MATRIKS KEPUTUSAN'!G77<=1,0.25,IF('MATRIKS KEPUTUSAN'!G77<=2,0.5,IF('MATRIKS KEPUTUSAN'!G77<=3,0.75,1))) -> 0.5 | H76: =IF('MATRIKS KEPUTUSAN'!H77<=11000000,0.25,IF('MATRIKS KEPUTUSAN'!H77<=14000000,0.5,IF('MATRIKS KEPUTUSAN'!H77<=17000000,0.75,1))) -> 0.75
A77: MAX Benefit / MIN Cost (referensi normalisasi) | D77: =MAX(D2:D76) -> 1 | E77: =MAX(E2:E76) -> 0.75 | F77: =MAX(F2:F76) -> 1 | G77: =MAX(G2:G76) -> 0.75 | H77: =MIN(H2:H76) -> 0.25

Sheet NORMALISASI
A1: MATRIKS NORMALISASI (R)
A2: MAX nilai fuzzy Benefit = 1,00 → r_ij = f_ij / 1 = f_ij | MIN nilai fuzzy Cost = 0,25 → r_ij = 0,25 / f_ij
A3: No | B3: Kode | C3: Nama Produk / Model | D3: r_C1 TKDN+BMP | E3: r_C2 RAM | F3: r_C3 SSD | G3: r_C4 Garansi | H3: r_C5 Harga
A4: ='NILAI FUZZY'!A2 -> 1 | B4: ='NILAI FUZZY'!B2 -> A01 | C4: ='NILAI FUZZY'!C2 -> Lenovo IdeaPad Slim 3 15IAH8 | D4: ='NILAI FUZZY'!D2 -> 0.25 | E4: ='NILAI FUZZY'!E2 -> 0.25 | F4: ='NILAI FUZZY'!F2 -> 0.67 | G4: ='NILAI FUZZY'!G2 -> 0.25 | H4: =0.25/'NILAI FUZZY'!H2 -> 0.5
A5: ='NILAI FUZZY'!A3 -> 2 | B5: ='NILAI FUZZY'!B3 -> A02 | C5: ='NILAI FUZZY'!C3 -> Lenovo IdeaPad Slim 3 15IAN8 | D5: ='NILAI FUZZY'!D3 -> 0.25 | E5: ='NILAI FUZZY'!E3 -> 0.5 | F5: ='NILAI FUZZY'!F3 -> 0.67 | G5: ='NILAI FUZZY'!G3 -> 0.25 | H5: =0.25/'NILAI FUZZY'!H3 -> 0.25
A6: ='NILAI FUZZY'!A4 -> 3 | B6: ='NILAI FUZZY'!B4 -> A03 | C6: ='NILAI FUZZY'!C4 -> Lenovo ThinkPad E14 Gen 5 | D6: ='NILAI FUZZY'!D4 -> 0.25 | E6: ='NILAI FUZZY'!E4 -> 0.5 | F6: ='NILAI FUZZY'!F4 -> 0.67 | G6: ='NILAI FUZZY'!G4 -> 0.25 | H6: =0.25/'NILAI FUZZY'!H4 -> 0.33333333
A7: ='NILAI FUZZY'!A5 -> 4 | B7: ='NILAI FUZZY'!B5 -> A04 | C7: ='NILAI FUZZY'!C5 -> Lenovo ThinkPad L14 Gen 4 | D7: ='NILAI FUZZY'!D5 -> 0.25 | E7: ='NILAI FUZZY'!E5 -> 0.25 | F7: ='NILAI FUZZY'!F5 -> 0.67 | G7: ='NILAI FUZZY'!G5 -> 0.75 | H7: =0.25/'NILAI FUZZY'!H5 -> 0.25
A8: ='NILAI FUZZY'!A6 -> 5 | B8: ='NILAI FUZZY'!B6 -> A05 | C8: ='NILAI FUZZY'!C6 -> Lenovo ThinkBook 14 G6 IRL | D8: ='NILAI FUZZY'!D6 -> 0.25 | E8: ='NILAI FUZZY'!E6 -> 0.25 | F8: ='NILAI FUZZY'!F6 -> 0.67 | G8: ='NILAI FUZZY'!G6 -> 0.5 | H8: =0.25/'NILAI FUZZY'!H6 -> 0.5
A9: ='NILAI FUZZY'!A7 -> 6 | B9: ='NILAI FUZZY'!B7 -> A06 | C9: ='NILAI FUZZY'!C7 -> ASUS Vivobook Go 14 E1404FA | D9: ='NILAI FUZZY'!D7 -> 1 | E9: ='NILAI FUZZY'!E7 -> 0.25 | F9: ='NILAI FUZZY'!F7 -> 0.67 | G9: ='NILAI FUZZY'!G7 -> 0.25 | H9: =0.25/'NILAI FUZZY'!H7 -> 0.33333333
A10: ='NILAI FUZZY'!A8 -> 7 | B10: ='NILAI FUZZY'!B8 -> A07 | C10: ='NILAI FUZZY'!C8 -> ASUS Vivobook 14 A1404ZA | D10: ='NILAI FUZZY'!D8 -> 0.25 | E10: ='NILAI FUZZY'!E8 -> 0.25 | F10: ='NILAI FUZZY'!F8 -> 0.67 | G10: ='NILAI FUZZY'!G8 -> 0.25 | H10: =0.25/'NILAI FUZZY'!H8 -> 0.5
A11: ='NILAI FUZZY'!A9 -> 8 | B11: ='NILAI FUZZY'!B9 -> A08 | C11: ='NILAI FUZZY'!C9 -> ASUS Vivobook 15 X1504ZA | D11: ='NILAI FUZZY'!D9 -> 0.25 | E11: ='NILAI FUZZY'!E9 -> 0.25 | F11: ='NILAI FUZZY'!F9 -> 0.67 | G11: ='NILAI FUZZY'!G9 -> 0.25 | H11: =0.25/'NILAI FUZZY'!H9 -> 0.5
A12: ='NILAI FUZZY'!A10 -> 9 | B12: ='NILAI FUZZY'!B10 -> A09 | C12: ='NILAI FUZZY'!C10 -> ASUS ExpertBook B1 B1402CVA-NK7110X | D12: ='NILAI FUZZY'!D10 -> 0.25 | E12: ='NILAI FUZZY'!E10 -> 0.5 | F12: ='NILAI FUZZY'!F10 -> 1 | G12: ='NILAI FUZZY'!G10 -> 0.75 | H12: =0.25/'NILAI FUZZY'!H10 -> 0.25
A13: ='NILAI FUZZY'!A11 -> 10 | B13: ='NILAI FUZZY'!B11 -> A10 | C13: ='NILAI FUZZY'!C11 -> ASUS ExpertBook B1 B1402CVA | D13: ='NILAI FUZZY'!D11 -> 0.25 | E13: ='NILAI FUZZY'!E11 -> 0.5 | F13: ='NILAI FUZZY'!F11 -> 1 | G13: ='NILAI FUZZY'!G11 -> 0.75 | H13: =0.25/'NILAI FUZZY'!H11 -> 0.25
A14: ='NILAI FUZZY'!A12 -> 11 | B14: ='NILAI FUZZY'!B12 -> A11 | C14: ='NILAI FUZZY'!C12 -> ASUS ExpertBook B5 B5402CVA | D14: ='NILAI FUZZY'!D12 -> 0.25 | E14: ='NILAI FUZZY'!E12 -> 0.25 | F14: ='NILAI FUZZY'!F12 -> 0.67 | G14: ='NILAI FUZZY'!G12 -> 0.25 | H14: =0.25/'NILAI FUZZY'!H12 -> 0.25
A15: ='NILAI FUZZY'!A13 -> 12 | B15: ='NILAI FUZZY'!B13 -> A12 | C15: ='NILAI FUZZY'!C13 -> ASUS ExpertBook P1 P1403CVA | D15: ='NILAI FUZZY'!D13 -> 1 | E15: ='NILAI FUZZY'!E13 -> 0.25 | F15: ='NILAI FUZZY'!F13 -> 0.67 | G15: ='NILAI FUZZY'!G13 -> 0.5 | H15: =0.25/'NILAI FUZZY'!H13 -> 1
... A78: ='NILAI FUZZY'!A76 -> 75 | B78: ='NILAI FUZZY'!B76 -> A75 | C78: ='NILAI FUZZY'!C76 -> Acer TravelMate P214 i3-1315U | D78: ='NILAI FUZZY'!D76 -> 0.25 | E78: ='NILAI FUZZY'!E76 -> 0.25 | F78: ='NILAI FUZZY'!F76 -> 0.67 | G78: ='NILAI FUZZY'!G76 -> 0.5 | H78: =0.25/'NILAI FUZZY'!H76 -> 0.33333333

Sheet NILAI PREFERENSI & RANKING
A1: NILAI PREFERENSI (V_i) DAN RANKING
A2: Bobot (W_j): | D2: 0.3 | E2: 0.25 | F2: 0.2 | G2: 0.15 | H2: 0.1
A3: No | B3: Kode | C3: Nama Produk / Model | D3: W×r_C1 TKDN + BMP | E3: W×r_C2 RAM | F3: W×r_C3 SSD | G3: W×r_C4 Garansi | H3: W×r_C5 Harga | I3: V_i (Nilai Preferensi) | J3: RANK | K3: RANK Unik
A4: =NORMALISASI!A4 -> 1 | B4: =NORMALISASI!B4 -> A01 | C4: =NORMALISASI!C4 -> Lenovo IdeaPad Slim 3 15IAH8 | D4: =D2*NORMALISASI!D4 -> 0.075 | E4: =E2*NORMALISASI!E4 -> 0.0625 | F4: =F2*NORMALISASI!F4 -> 0.134 | G4: =G2*NORMALISASI!G4 -> 0.0375 | H4: =H2*NORMALISASI!H4 -> 0.05 | I4: =ROUND(SUM(D4:H4), 4) -> 0.359 | J4: =RANK(I4,I$4:I$78,0) -> 51 | K4: =RANK(I4,$I$4:$I$78,0)+COUNTIF($I$4:I4,I4)-1 -> 51
A5: =NORMALISASI!A5 -> 2 | B5: =NORMALISASI!B5 -> A02 | C5: =NORMALISASI!C5 -> Lenovo IdeaPad Slim 3 15IAN8 | D5: =D2*NORMALISASI!D5 -> 0.075 | E5: =E2*NORMALISASI!E5 -> 0.125 | F5: =F2*NORMALISASI!F5 -> 0.134 | G5: =G2*NORMALISASI!G5 -> 0.0375 | H5: =H2*NORMALISASI!H5 -> 0.025 | I5: =ROUND(SUM(D5:H5), 4) -> 0.3965 | J5: =RANK(I5,I$4:I$78,0) -> 40 | K5: =RANK(I5,$I$4:$I$78,0)+COUNTIF($I$4:I5,I5)-1 -> 40
A6: =NORMALISASI!A6 -> 3 | B6: =NORMALISASI!B6 -> A03 | C6: =NORMALISASI!C6 -> Lenovo ThinkPad E14 Gen 5 | D6: =D2*NORMALISASI!D6 -> 0.075 | E6: =E2*NORMALISASI!E6 -> 0.125 | F6: =F2*NORMALISASI!F6 -> 0.134 | G6: =G2*NORMALISASI!G6 -> 0.0375 | H6: =H2*NORMALISASI!H6 -> 0.033333333 | I6: =ROUND(SUM(D6:H6), 4) -> 0.4048 | J6: =RANK(I6,I$4:I$78,0) -> 36 | K6: =RANK(I6,$I$4:$I$78,0)+COUNTIF($I$4:I6,I6)-1 -> 36
A7: =NORMALISASI!A7 -> 4 | B7: =NORMALISASI!B7 -> A04 | C7: =NORMALISASI!C7 -> Lenovo ThinkPad L14 Gen 4 | D7: =D2*NORMALISASI!D7 -> 0.075 | E7: =E2*NORMALISASI!E7 -> 0.0625 | F7: =F2*NORMALISASI!F7 -> 0.134 | G7: =G2*NORMALISASI!G7 -> 0.1125 | H7: =H2*NORMALISASI!H7 -> 0.025 | I7: =ROUND(SUM(D7:H7), 4) -> 0.409 | J7: =RANK(I7,I$4:I$78,0) -> 30 | K7: =RANK(I7,$I$4:$I$78,0)+COUNTIF($I$4:I7,I7)-1 -> 30
A8: =NORMALISASI!A8 -> 5 | B8: =NORMALISASI!B8 -> A05 | C8: =NORMALISASI!C8 -> Lenovo ThinkBook 14 G6 IRL | D8: =D2*NORMALISASI!D8 -> 0.075 | E8: =E2*NORMALISASI!E8 -> 0.0625 | F8: =F2*NORMALISASI!F8 -> 0.134 | G8: =G2*NORMALISASI!G8 -> 0.075 | H8: =H2*NORMALISASI!H8 -> 0.05 | I8: =ROUND(SUM(D8:H8), 4) -> 0.3965 | J8: =RANK(I8,I$4:I$78,0) -> 40 | K8: =RANK(I8,$I$4:$I$78,0)+COUNTIF($I$4:I8,I8)-1 -> 41
A9: =NORMALISASI!A9 -> 6 | B9: =NORMALISASI!B9 -> A06 | C9: =NORMALISASI!C9 -> ASUS Vivobook Go 14 E1404FA | D9: =D2*NORMALISASI!D9 -> 0.3 | E9: =E2*NORMALISASI!E9 -> 0.0625 | F9: =F2*NORMALISASI!F9 -> 0.134 | G9: =G2*NORMALISASI!G9 -> 0.0375 | H9: =H2*NORMALISASI!H9 -> 0.033333333 | I9: =ROUND(SUM(D9:H9), 4) -> 0.5673 | J9: =RANK(I9,I$4:I$78,0) -> 2 | K9: =RANK(I9,$I$4:$I$78,0)+COUNTIF($I$4:I9,I9)-1 -> 2
A10: =NORMALISASI!A10 -> 7 | B10: =NORMALISASI!B10 -> A07 | C10: =NORMALISASI!C10 -> ASUS Vivobook 14 A1404ZA | D10: =D2*NORMALISASI!D10 -> 0.075 | E10: =E2*NORMALISASI!E10 -> 0.0625 | F10: =F2*NORMALISASI!F10 -> 0.134 | G10: =G2*NORMALISASI!G10 -> 0.0375 | H10: =H2*NORMALISASI!H10 -> 0.05 | I10: =ROUND(SUM(D10:H10), 4) -> 0.359 | J10: =RANK(I10,I$4:I$78,0) -> 51 | K10: =RANK(I10,$I$4:$I$78,0)+COUNTIF($I$4:I10,I10)-1 -> 52
A11: =NORMALISASI!A11 -> 8 | B11: =NORMALISASI!B11 -> A08 | C11: =NORMALISASI!C11 -> ASUS Vivobook 15 X1504ZA | D11: =D2*NORMALISASI!D11 -> 0.075 | E11: =E2*NORMALISASI!E11 -> 0.0625 | F11: =F2*NORMALISASI!F11 -> 0.134 | G11: =G2*NORMALISASI!G11 -> 0.0375 | H11: =H2*NORMALISASI!H11 -> 0.05 | I11: =ROUND(SUM(D11:H11), 4) -> 0.359 | J11: =RANK(I11,I$4:I$78,0) -> 51 | K11: =RANK(I11,$I$4:$I$78,0)+COUNTIF($I$4:I11,I11)-1 -> 53
A12: =NORMALISASI!A12 -> 9 | B12: =NORMALISASI!B12 -> A09 | C12: =NORMALISASI!C12 -> ASUS ExpertBook B1 B1402CVA-NK7110X | D12: =D2*NORMALISASI!D12 -> 0.075 | E12: =E2*NORMALISASI!E12 -> 0.125 | F12: =F2*NORMALISASI!F12 -> 0.2 | G12: =G2*NORMALISASI!G12 -> 0.1125 | H12: =H2*NORMALISASI!H12 -> 0.025 | I12: =ROUND(SUM(D12:H12), 4) -> 0.5375 | J12: =RANK(I12,I$4:I$78,0) -> 4 | K12: =RANK(I12,$I$4:$I$78,0)+COUNTIF($I$4:I12,I12)-1 -> 4
A13: =NORMALISASI!A13 -> 10 | B13: =NORMALISASI!B13 -> A10 | C13: =NORMALISASI!C13 -> ASUS ExpertBook B1 B1402CVA | D13: =D2*NORMALISASI!D13 -> 0.075 | E13: =E2*NORMALISASI!E13 -> 0.125 | F13: =F2*NORMALISASI!F13 -> 0.2 | G13: =G2*NORMALISASI!G13 -> 0.1125 | H13: =H2*NORMALISASI!H13 -> 0.025 | I13: =ROUND(SUM(D13:H13), 4) -> 0.5375 | J13: =RANK(I13,I$4:I$78,0) -> 4 | K13: =RANK(I13,$I$4:$I$78,0)+COUNTIF($I$4:I13,I13)-1 -> 5
A14: =NORMALISASI!A14 -> 11 | B14: =NORMALISASI!B14 -> A11 | C14: =NORMALISASI!C14 -> ASUS ExpertBook B5 B5402CVA | D14: =D2*NORMALISASI!D14 -> 0.075 | E14: =E2*NORMALISASI!E14 -> 0.0625 | F14: =F2*NORMALISASI!F14 -> 0.134 | G14: =G2*NORMALISASI!G14 -> 0.0375 | H14: =H2*NORMALISASI!H14 -> 0.025 | I14: =ROUND(SUM(D14:H14), 4) -> 0.334 | J14: =RANK(I14,I$4:I$78,0) -> 70 | K14: =RANK(I14,$I$4:$I$78,0)+COUNTIF($I$4:I14,I14)-1 -> 70
A15: =NORMALISASI!A15 -> 12 | B15: =NORMALISASI!B15 -> A12 | C15: =NORMALISASI!C15 -> ASUS ExpertBook P1 P1403CVA | D15: =D2*NORMALISASI!D15 -> 0.3 | E15: =E2*NORMALISASI!E15 -> 0.0625 | F15: =F2*NORMALISASI!F15 -> 0.134 | G15: =G2*NORMALISASI!G15 -> 0.075 | H15: =H2*NORMALISASI!H15 -> 0.1 | I15: =ROUND(SUM(D15:H15), 4) -> 0.6715 | J15: =RANK(I15,I$4:I$78,0) -> 1 | K15: =RANK(I15,$I$4:$I$78,0)+COUNTIF($I$4:I15,I15)-1 -> 1
A16: =NORMALISASI!A16 -> 13 | B16: =NORMALISASI!B16 -> A13 | C16: =NORMALISASI!C16 -> HP 14S EP0001TU/EP0002TU i5-1335U | D16: =D2*NORMALISASI!D16 -> 0.075 | E16: =E2*NORMALISASI!E16 -> 0.0625 | F16: =F2*NORMALISASI!F16 -> 0.134 | G16: =G2*NORMALISASI!G16 -> 0.0375 | H16: =H2*NORMALISASI!H16 -> 0.1 | I16: =ROUND(SUM(D16:H16), 4) -> 0.409 | J16: =RANK(I16,I$4:I$78,0) -> 30 | K16: =RANK(I16,$I$4:$I$78,0)+COUNTIF($I$4:I16,I16)-1 -> 31
A17: =NORMALISASI!A17 -> 14 | B17: =NORMALISASI!B17 -> A14 | C17: =NORMALISASI!C17 -> HP 14S-DQ5567TU i3-1215U | D17: =D2*NORMALISASI!D17 -> 0.075 | E17: =E2*NORMALISASI!E17 -> 0.0625 | F17: =F2*NORMALISASI!F17 -> 0.134 | G17: =G2*NORMALISASI!G17 -> 0.075 | H17: =H2*NORMALISASI!H17 -> 0.1 | I17: =ROUND(SUM(D17:H17), 4) -> 0.4465 | J17: =RANK(I17,I$4:I$78,0) -> 19 | K17: =RANK(I17,$I$4:$I$78,0)+COUNTIF($I$4:I17,I17)-1 -> 19
A18: =NORMALISASI!A18 -> 15 | B18: =NORMALISASI!B18 -> A15 | C18: =NORMALISASI!C18 -> HP 14S DQ5153TU i5-1235U | D18: =D2*NORMALISASI!D18 -> 0.075 | E18: =E2*NORMALISASI!E18 -> 0.0625 | F18: =F2*NORMALISASI!F18 -> 0.134 | G18: =G2*NORMALISASI!G18 -> 0.0375 | H18: =H2*NORMALISASI!H18 -> 0.05 | I18: =ROUND(SUM(D18:H18), 4) -> 0.359 | J18: =RANK(I18,I$4:I$78,0) -> 51 | K18: =RANK(I18,$I$4:$I$78,0)+COUNTIF($I$4:I18,I18)-1 -> 54
A19: =NORMALISASI!A19 -> 16 | B19: =NORMALISASI!B19 -> A16 | C19: =NORMALISASI!C19 -> HP 14S DQ5152TU i5 1235U | D19: =D2*NORMALISASI!D19 -> 0.075 | E19: =E2*NORMALISASI!E19 -> 0.0625 | F19: =F2*NORMALISASI!F19 -> 0.134 | G19: =G2*NORMALISASI!G19 -> 0.075 | H19: =H2*NORMALISASI!H19 -> 0.05 | I19: =ROUND(SUM(D19:H19), 4) -> 0.3965 | J19: =RANK(I19,I$4:I$78,0) -> 40 | K19: =RANK(I19,$I$4:$I$78,0)+COUNTIF($I$4:I19,I19)-1 -> 42
A20: =NORMALISASI!A20 -> 17 | B20: =NORMALISASI!B20 -> A17 | C20: =NORMALISASI!C20 -> HP 14s DQ5000TU i5-1240P | D20: =D2*NORMALISASI!D20 -> 0.075 | E20: =E2*NORMALISASI!E20 -> 0.0625 | F20: =F2*NORMALISASI!F20 -> 0.134 | G20: =G2*NORMALISASI!G20 -> 0.075 | H20: =H2*NORMALISASI!H20 -> 0.033333333 | I20: =ROUND(SUM(D20:H20), 4) -> 0.3798 | J20: =RANK(I20,I$4:I$78,0) -> 47 | K20: =RANK(I20,$I$4:$I$78,0)+COUNTIF($I$4:I20,I20)-1 -> 47
A21: =NORMALISASI!A21 -> 18 | B21: =NORMALISASI!B21 -> A18 | C21: =NORMALISASI!C21 -> Acer TravelMate P214 Ryzen 5 PRO | D21: =D2*NORMALISASI!D21 -> 0.075 | E21: =E2*NORMALISASI!E21 -> 0.0625 | F21: =F2*NORMALISASI!F21 -> 0.134 | G21: =G2*NORMALISASI!G21 -> 0.0375 | H21: =H2*NORMALISASI!H21 -> 0.033333333 | I21: =ROUND(SUM(D21:H21), 4) -> 0.3423 | J21: =RANK(I21,I$4:I$78,0) -> 62 | K21: =RANK(I21,$I$4:$I$78,0)+COUNTIF($I$4:I21,I21)-1 -> 62
A22: =NORMALISASI!A22 -> 19 | B22: =NORMALISASI!B22 -> A19 | C22: =NORMALISASI!C22 -> Acer TravelMate P214 Intel Core 5 120U | D22: =D2*NORMALISASI!D22 -> 0.15 | E22: =E2*NORMALISASI!E22 -> 0.0625 | F22: =F2*NORMALISASI!F22 -> 0.134 | G22: =G2*NORMALISASI!G22 -> 0.075 | H22: =H2*NORMALISASI!H22 -> 0.033333333 | I22: =ROUND(SUM(D22:H22), 4) -> 0.4548 | J22: =RANK(I22,I$4:I$78,0) -> 17 | K22: =RANK(I22,$I$4:$I$78,0)+COUNTIF($I$4:I22,I22)-1 -> 17
A23: =NORMALISASI!A23 -> 20 | B23: =NORMALISASI!B23 -> A20 | C23: =NORMALISASI!C23 -> Acer TravelMate P414 Core-i5-1240P | D23: =D2*NORMALISASI!D23 -> 0.075 | E23: =E2*NORMALISASI!E23 -> 0.125 | F23: =F2*NORMALISASI!F23 -> 0.134 | G23: =G2*NORMALISASI!G23 -> 0.1125 | H23: =H2*NORMALISASI!H23 -> 0.025 | I23: =ROUND(SUM(D23:H23), 4) -> 0.4715 | J23: =RANK(I23,I$4:I$78,0) -> 11 | K23: =RANK(I23,$I$4:$I$78,0)+COUNTIF($I$4:I23,I23)-1 -> 11
A24: =NORMALISASI!A24 -> 21 | B24: =NORMALISASI!B24 -> A21 | C24: =NORMALISASI!C24 -> Acer TravelMate P214 Core-i5-0041 | D24: =D2*NORMALISASI!D24 -> 0.15 | E24: =E2*NORMALISASI!E24 -> 0.0625 | F24: =F2*NORMALISASI!F24 -> 0.134 | G24: =G2*NORMALISASI!G24 -> 0.0375 | H24: =H2*NORMALISASI!H24 -> 0.033333333 | I24: =ROUND(SUM(D24:H24), 4) -> 0.4173 | J24: =RANK(I24,I$4:I$78,0) -> 27 | K24: =RANK(I24,$I$4:$I$78,0)+COUNTIF($I$4:I24,I24)-1 -> 27
A25: =NORMALISASI!A25 -> 22 | B25: =NORMALISASI!B25 -> A22 | C25: =NORMALISASI!C25 -> Acer Travelmate P414 i7-1260P 106986 | D25: =D2*NORMALISASI!D25 -> 0.075 | E25: =E2*NORMALISASI!E25 -> 0.125 | F25: =F2*NORMALISASI!F25 -> 0.2 | G25: =G2*NORMALISASI!G25 -> 0.0375 | H25: =H2*NORMALISASI!H25 -> 0.025 | I25: =ROUND(SUM(D25:H25), 4) -> 0.4625 | J25: =RANK(I25,I$4:I$78,0) -> 13 | K25: =RANK(I25,$I$4:$I$78,0)+COUNTIF($I$4:I25,I25)-1 -> 13
A26: =NORMALISASI!A26 -> 23 | B26: =NORMALISASI!B26 -> A23 | C26: =NORMALISASI!C26 -> Acer Travelmate P414 Intel Core Ultra 7-155U | D26: =D2*NORMALISASI!D26 -> 0.075 | E26: =E2*NORMALISASI!E26 -> 0.125 | F26: =F2*NORMALISASI!F26 -> 0.2 | G26: =G2*NORMALISASI!G26 -> 0.1125 | H26: =H2*NORMALISASI!H26 -> 0.025 | I26: =ROUND(SUM(D26:H26), 4) -> 0.5375 | J26: =RANK(I26,I$4:I$78,0) -> 4 | K26: =RANK(I26,$I$4:$I$78,0)+COUNTIF($I$4:I26,I26)-1 -> 6
A27: =NORMALISASI!A27 -> 24 | B27: =NORMALISASI!B27 -> A24 | C27: =NORMALISASI!C27 -> Acer Travelmate P214 i5 82022 | D27: =D2*NORMALISASI!D27 -> 0.075 | E27: =E2*NORMALISASI!E27 -> 0.0625 | F27: =F2*NORMALISASI!F27 -> 0.134 | G27: =G2*NORMALISASI!G27 -> 0.0375 | H27: =H2*NORMALISASI!H27 -> 0.05 | I27: =ROUND(SUM(D27:H27), 4) -> 0.359 | J27: =RANK(I27,I$4:I$78,0) -> 51 | K27: =RANK(I27,$I$4:$I$78,0)+COUNTIF($I$4:I27,I27)-1 -> 55
A28: =NORMALISASI!A28 -> 25 | B28: =NORMALISASI!B28 -> A25 | C28: =NORMALISASI!C28 -> Acer Travelmate P214 i5-1334U | D28: =D2*NORMALISASI!D28 -> 0.075 | E28: =E2*NORMALISASI!E28 -> 0.0625 | F28: =F2*NORMALISASI!F28 -> 0.134 | G28: =G2*NORMALISASI!G28 -> 0.1125 | H28: =H2*NORMALISASI!H28 -> 0.025 | I28: =ROUND(SUM(D28:H28), 4) -> 0.409 | J28: =RANK(I28,I$4:I$78,0) -> 30 | K28: =RANK(I28,$I$4:$I$78,0)+COUNTIF($I$4:I28,I28)-1 -> 32
A29: =NORMALISASI!A29 -> 26 | B29: =NORMALISASI!B29 -> A26 | C29: =NORMALISASI!C29 -> Acer Travelmate P214 i7-1355U | D29: =D2*NORMALISASI!D29 -> 0.075 | E29: =E2*NORMALISASI!E29 -> 0.0625 | F29: =F2*NORMALISASI!F29 -> 0.134 | G29: =G2*NORMALISASI!G29 -> 0.0375 | H29: =H2*NORMALISASI!H29 -> 0.033333333 | I29: =ROUND(SUM(D29:H29), 4) -> 0.3423 | J29: =RANK(I29,I$4:I$78,0) -> 62 | K29: =RANK(I29,$I$4:$I$78,0)+COUNTIF($I$4:I29,I29)-1 -> 63
A30: =NORMALISASI!A30 -> 27 | B30: =NORMALISASI!B30 -> A27 | C30: =NORMALISASI!C30 -> Acer TravelMate P214 TMP214/0034 | D30: =D2*NORMALISASI!D30 -> 0.075 | E30: =E2*NORMALISASI!E30 -> 0.0625 | F30: =F2*NORMALISASI!F30 -> 0.134 | G30: =G2*NORMALISASI!G30 -> 0.1125 | H30: =H2*NORMALISASI!H30 -> 0.033333333 | I30: =ROUND(SUM(D30:H30), 4) -> 0.4173 | J30: =RANK(I30,I$4:I$78,0) -> 27 | K30: =RANK(I30,$I$4:$I$78,0)+COUNTIF($I$4:I30,I30)-1 -> 28
A31: =NORMALISASI!A31 -> 28 | B31: =NORMALISASI!B31 -> A28 | C31: =NORMALISASI!C31 -> Acer TravelMate P2 Core i3 | D31: =D2*NORMALISASI!D31 -> 0.075 | E31: =E2*NORMALISASI!E31 -> 0.0625 | F31: =F2*NORMALISASI!F31 -> 0.134 | G31: =G2*NORMALISASI!G31 -> 0.0375 | H31: =H2*NORMALISASI!H31 -> 0.05 | I31: =ROUND(SUM(D31:H31), 4) -> 0.359 | J31: =RANK(I31,I$4:I$78,0) -> 51 | K31: =RANK(I31,$I$4:$I$78,0)+COUNTIF($I$4:I31,I31)-1 -> 56
A32: =NORMALISASI!A32 -> 29 | B32: =NORMALISASI!B32 -> A29 | C32: =NORMALISASI!C32 -> Acer Travelmate i5-1235U | D32: =D2*NORMALISASI!D32 -> 0.075 | E32: =E2*NORMALISASI!E32 -> 0.0625 | F32: =F2*NORMALISASI!F32 -> 0.134 | G32: =G2*NORMALISASI!G32 -> 0.0375 | H32: =H2*NORMALISASI!H32 -> 0.025 | I32: =ROUND(SUM(D32:H32), 4) -> 0.334 | J32: =RANK(I32,I$4:I$78,0) -> 70 | K32: =RANK(I32,$I$4:$I$78,0)+COUNTIF($I$4:I32,I32)-1 -> 71
A33: =NORMALISASI!A33 -> 30 | B33: =NORMALISASI!B33 -> A30 | C33: =NORMALISASI!C33 -> Acer Travelmate i5-1135G7 | D33: =D2*NORMALISASI!D33 -> 0.075 | E33: =E2*NORMALISASI!E33 -> 0.0625 | F33: =F2*NORMALISASI!F33 -> 0.134 | G33: =G2*NORMALISASI!G33 -> 0.0375 | H33: =H2*NORMALISASI!H33 -> 0.05 | I33: =ROUND(SUM(D33:H33), 4) -> 0.359 | J33: =RANK(I33,I$4:I$78,0) -> 51 | K33: =RANK(I33,$I$4:$I$78,0)+COUNTIF($I$4:I33,I33)-1 -> 57
A34: =NORMALISASI!A34 -> 31 | B34: =NORMALISASI!B34 -> A31 | C34: =NORMALISASI!C34 -> Acer TravelMate P2 TMP214 54 | D34: =D2*NORMALISASI!D34 -> 0.075 | E34: =E2*NORMALISASI!E34 -> 0.125 | F34: =F2*NORMALISASI!F34 -> 0.134 | G34: =G2*NORMALISASI!G34 -> 0.0375 | H34: =H2*NORMALISASI!H34 -> 0.033333333 | I34: =ROUND(SUM(D34:H34), 4) -> 0.4048 | J34: =RANK(I34,I$4:I$78,0) -> 36 | K34: =RANK(I34,$I$4:$I$78,0)+COUNTIF($I$4:I34,I34)-1 -> 37
A35: =NORMALISASI!A35 -> 32 | B35: =NORMALISASI!B35 -> A32 | C35: =NORMALISASI!C35 -> Acer TravelMate P2 TMP214-54-5816 | D35: =D2*NORMALISASI!D35 -> 0.075 | E35: =E2*NORMALISASI!E35 -> 0.125 | F35: =F2*NORMALISASI!F35 -> 0.134 | G35: =G2*NORMALISASI!G35 -> 0.0375 | H35: =H2*NORMALISASI!H35 -> 0.033333333 | I35: =ROUND(SUM(D35:H35), 4) -> 0.4048 | J35: =RANK(I35,I$4:I$78,0) -> 36 | K35: =RANK(I35,$I$4:$I$78,0)+COUNTIF($I$4:I35,I35)-1 -> 38
A36: =NORMALISASI!A36 -> 33 | B36: =NORMALISASI!B36 -> A33 | C36: =NORMALISASI!C36 -> Acer Travelmate P214 | D36: =D2*NORMALISASI!D36 -> 0.075 | E36: =E2*NORMALISASI!E36 -> 0.0625 | F36: =F2*NORMALISASI!F36 -> 0.134 | G36: =G2*NORMALISASI!G36 -> 0.075 | H36: =H2*NORMALISASI!H36 -> 0.05 | I36: =ROUND(SUM(D36:H36), 4) -> 0.3965 | J36: =RANK(I36,I$4:I$78,0) -> 40 | K36: =RANK(I36,$I$4:$I$78,0)+COUNTIF($I$4:I36,I36)-1 -> 43
A37: =NORMALISASI!A37 -> 34 | B37: =NORMALISASI!B37 -> A34 | C37: =NORMALISASI!C37 -> Acer TravelMate P214 i7-1165G7 | D37: =D2*NORMALISASI!D37 -> 0.075 | E37: =E2*NORMALISASI!E37 -> 0.0625 | F37: =F2*NORMALISASI!F37 -> 0.134 | G37: =G2*NORMALISASI!G37 -> 0.075 | H37: =H2*NORMALISASI!H37 -> 0.025 | I37: =ROUND(SUM(D37:H37), 4) -> 0.3715 | J37: =RANK(I37,I$4:I$78,0) -> 49 | K37: =RANK(I37,$I$4:$I$78,0)+COUNTIF($I$4:I37,I37)-1 -> 49
A38: =NORMALISASI!A38 -> 35 | B38: =NORMALISASI!B38 -> A35 | C38: =NORMALISASI!C38 -> Acer Travelmate P414 i7-1260P | D38: =D2*NORMALISASI!D38 -> 0.075 | E38: =E2*NORMALISASI!E38 -> 0.125 | F38: =F2*NORMALISASI!F38 -> 0.2 | G38: =G2*NORMALISASI!G38 -> 0.1125 | H38: =H2*NORMALISASI!H38 -> 0.025 | I38: =ROUND(SUM(D38:H38), 4) -> 0.5375 | J38: =RANK(I38,I$4:I$78,0) -> 4 | K38: =RANK(I38,$I$4:$I$78,0)+COUNTIF($I$4:I38,I38)-1 -> 7
A39: =NORMALISASI!A39 -> 36 | B39: =NORMALISASI!B39 -> A36 | C39: =NORMALISASI!C39 -> Axioo Mybook | D39: =D2*NORMALISASI!D39 -> 0.15 | E39: =E2*NORMALISASI!E39 -> 0.0625 | F39: =F2*NORMALISASI!F39 -> 0.066 | G39: =G2*NORMALISASI!G39 -> 0.0375 | H39: =H2*NORMALISASI!H39 -> 0.1 | I39: =ROUND(SUM(D39:H39), 4) -> 0.416 | J39: =RANK(I39,I$4:I$78,0) -> 29 | K39: =RANK(I39,$I$4:$I$78,0)+COUNTIF($I$4:I39,I39)-1 -> 29
A40: =NORMALISASI!A40 -> 37 | B40: =NORMALISASI!B40 -> A37 | C40: =NORMALISASI!C40 -> Axioo Mybook Prime E7 (16N5-3) | D40: =D2*NORMALISASI!D40 -> 0.075 | E40: =E2*NORMALISASI!E40 -> 0.125 | F40: =F2*NORMALISASI!F40 -> 0.134 | G40: =G2*NORMALISASI!G40 -> 0.0375 | H40: =H2*NORMALISASI!H40 -> 0.025 | I40: =ROUND(SUM(D40:H40), 4) -> 0.3965 | J40: =RANK(I40,I$4:I$78,0) -> 40 | K40: =RANK(I40,$I$4:$I$78,0)+COUNTIF($I$4:I40,I40)-1 -> 44
...

Sheet HASIL AKHIR
A1: HASIL AKHIR – RANKING LAPTOP TERBAIK BERDASARKAN METODE SAW
A2: Data diurutkan berdasarkan nilai preferensi V_i tertinggi → terendah (SMALL/LARGE formula menggunakan helper kolom)
A4: RANK | B4: Kode | C4: Nama Produk / Model | D4: Merek | E4: C1 TKDN + BMP (%) | F4: C2 RAM (GB) | G4: C3 SSD (GB) | H4: C4 Garansi (Thn) | I4: C5 Harga (Rp) | J4: V_i (Nilai Preferensi) | K4: KETERANGAN
A5: 1 | B5: {=INDEX('DATA ALTERNATIF'!$B$5:$B$79, MATCH(A5, 'NILAI PREFERENSI & RANKING'!$K$4:$K$78, 0))} -> A12 | C5: {=INDEX('DATA ALTERNATIF'!$C$5:$C$79, MATCH(A5, 'NILAI PREFERENSI & RANKING'!$K$4:$K$78, 0))} -> ASUS ExpertBook P1 P1403CVA | D5: {=INDEX('DATA ALTERNATIF'!$D$5:$D$79, MATCH(A5, 'NILAI PREFERENSI & RANKING'!$K$4:$K$78, 0))} -> ASUS | E5: {=INDEX('DATA ALTERNATIF'!$E$5:$E$79, MATCH(A5, 'NILAI PREFERENSI & RANKING'!$K$4:$K$78, 0))} -> 45,32 | F5: {=INDEX('DATA ALTERNATIF'!$F$5:$F$79, MATCH(A5, 'NILAI PREFERENSI & RANKING'!$K$4:$K$78, 0))} -> 8 | G5: {=INDEX('DATA ALTERNATIF'!$G$5:$G$79, MATCH(A5, 'NILAI PREFERENSI & RANKING'!$K$4:$K$78, 0))} -> 512 | H5: {=INDEX('DATA ALTERNATIF'!$H$5:$H$79, MATCH(A5, 'NILAI PREFERENSI & RANKING'!$K$4:$K$78, 0))} -> 2 | I5: {=INDEX('DATA ALTERNATIF'!$I$5:$I$79, MATCH(A5, 'NILAI PREFERENSI & RANKING'!$K$4:$K$78, 0))} -> 9967000 | J5: {=INDEX('NILAI PREFERENSI & RANKING'!$I$4:$I$78, MATCH(A5, 'NILAI PREFERENSI & RANKING'!$K$4:$K$78, 0))} -> 0.6715 | K5: 1
A6: 2 | B6: {=INDEX('DATA ALTERNATIF'!$B$5:$B$79, MATCH(A6, 'NILAI PREFERENSI & RANKING'!$K$4:$K$78, 0))} -> A06 | C6: {=INDEX('DATA ALTERNATIF'!$C$5:$C$79, MATCH(A6, 'NILAI PREFERENSI & RANKING'!$K$4:$K$78, 0))} -> ASUS Vivobook Go 14 E1404FA | D6: {=INDEX('DATA ALTERNATIF'!$D$5:$D$79, MATCH(A6, 'NILAI PREFERENSI & RANKING'!$K$4:$K$78, 0))} -> ASUS | E6: {=INDEX('DATA ALTERNATIF'!$E$5:$E$79, MATCH(A6, 'NILAI PREFERENSI & RANKING'!$K$4:$K$78, 0))} -> 44,45 | F6: {=INDEX('DATA ALTERNATIF'!$F$5:$F$79, MATCH(A6, 'NILAI PREFERENSI & RANKING'!$K$4:$K$78, 0))} -> 8 | G6: {=INDEX('DATA ALTERNATIF'!$G$5:$G$79, MATCH(A6, 'NILAI PREFERENSI & RANKING'!$K$4:$K$78, 0))} -> 512 | H6: {=INDEX('DATA ALTERNATIF'!$H$5:$H$79, MATCH(A6, 'NILAI PREFERENSI & RANKING'!$K$4:$K$78, 0))} -> 1 | I6: {=INDEX('DATA ALTERNATIF'!$I$5:$I$79, MATCH(A6, 'NILAI PREFERENSI & RANKING'!$K$4:$K$78, 0))} -> 14041500 | J6: {=INDEX('NILAI PREFERENSI & RANKING'!$I$4:$I$78, MATCH(A6, 'NILAI PREFERENSI & RANKING'!$K$4:$K$78, 0))} -> 0.5673 | K6: 2
A7: 3 | B7: {=INDEX('DATA ALTERNATIF'!$B$5:$B$79, MATCH(A7, 'NILAI PREFERENSI & RANKING'!$K$4:$K$78, 0))} -> A45 | C7: {=INDEX('DATA ALTERNATIF'!$C$5:$C$79, MATCH(A7, 'NILAI PREFERENSI & RANKING'!$K$4:$K$78, 0))} -> ASUSVivobook Go 14 | D7: {=INDEX('DATA ALTERNATIF'!$D$5:$D$79, MATCH(A7, 'NILAI PREFERENSI & RANKING'!$K$4:$K$78, 0))} -> ASUS | E7: {=INDEX('DATA ALTERNATIF'!$E$5:$E$79, MATCH(A7, 'NILAI PREFERENSI & RANKING'!$K$4:$K$78, 0))} -> 45.32 | F7: {=INDEX('DATA ALTERNATIF'!$F$5:$F$79, MATCH(A7, 'NILAI PREFERENSI & RANKING'!$K$4:$K$78, 0))} -> 8 | G7: {=INDEX('DATA ALTERNATIF'!$G$5:$G$79, MATCH(A7, 'NILAI PREFERENSI & RANKING'!$K$4:$K$78, 0))} -> 512 | H7: {=INDEX('DATA ALTERNATIF'!$H$5:$H$79, MATCH(A7, 'NILAI PREFERENSI & RANKING'!$K$4:$K$78, 0))} -> 3 | I7: {=INDEX('DATA ALTERNATIF'!$I$5:$I$79, MATCH(A7, 'NILAI PREFERENSI & RANKING'!$K$4:$K$78, 0))} -> 9399999 | J7: {=INDEX('NILAI PREFERENSI & RANKING'!$I$4:$I$78, MATCH(A7, 'NILAI PREFERENSI & RANKING'!$K$4:$K$78, 0))} -> 0.559 | K7: 3
A8: 4 | B8: {=INDEX('DATA ALTERNATIF'!$B$5:$B$79, MATCH(A8, 'NILAI PREFERENSI & RANKING'!$K$4:$K$78, 0))} -> A09 | C8: {=INDEX('DATA ALTERNATIF'!$C$5:$C$79, MATCH(A8, 'NILAI PREFERENSI & RANKING'!$K$4:$K$78, 0))} -> ASUS ExpertBook B1 B1402CVA-NK7110X | D8: {=INDEX('DATA ALTERNATIF'!$D$5:$D$79, MATCH(A8, 'NILAI PREFERENSI & RANKING'!$K$4:$K$78, 0))} -> ASUS | E8: {=INDEX('DATA ALTERNATIF'!$E$5:$E$79, MATCH(A8, 'NILAI PREFERENSI & RANKING'!$K$4:$K$78, 0))} -> 41.3 | F8: {=INDEX('DATA ALTERNATIF'!$F$5:$F$79, MATCH(A8, 'NILAI PREFERENSI & RANKING'!$K$4:$K$78, 0))} -> 16 | G8: {=INDEX('DATA ALTERNATIF'!$G$5:$G$79, MATCH(A8, 'NILAI PREFERENSI & RANKING'!$K$4:$K$78, 0))} -> 1024 | H8: {=INDEX('DATA ALTERNATIF'!$H$5:$H$79, MATCH(A8, 'NILAI PREFERENSI & RANKING'!$K$4:$K$78, 0))} -> 3 | I8: {=INDEX('DATA ALTERNATIF'!$I$5:$I$79, MATCH(A8, 'NILAI PREFERENSI & RANKING'!$K$4:$K$78, 0))} -> 21959000 | J8: {=INDEX('NILAI PREFERENSI & RANKING'!$I$4:$I$78, MATCH(A8, 'NILAI PREFERENSI & RANKING'!$K$4:$K$78, 0))} -> 0.5375 | K8: Rekomendasi
A9: 5 | B9: {=INDEX('DATA ALTERNATIF'!$B$5:$B$79, MATCH(A9, 'NILAI PREFERENSI & RANKING'!$K$4:$K$78, 0))} -> A10 | C9: {=INDEX('DATA ALTERNATIF'!$C$5:$C$79, MATCH(A9, 'NILAI PREFERENSI & RANKING'!$K$4:$K$78, 0))} -> ASUS ExpertBook B1 B1402CVA | D9: {=INDEX('DATA ALTERNATIF'!$D$5:$D$79, MATCH(A9, 'NILAI PREFERENSI & RANKING'!$K$4:$K$78, 0))} -> ASUS | E9: {=INDEX('DATA ALTERNATIF'!$E$5:$E$79, MATCH(A9, 'NILAI PREFERENSI & RANKING'!$K$4:$K$78, 0))} -> 41.3 | F9: {=INDEX('DATA ALTERNATIF'!$F$5:$F$79, MATCH(A9, 'NILAI PREFERENSI & RANKING'!$K$4:$K$78, 0))} -> 16 | G9: {=INDEX('DATA ALTERNATIF'!$G$5:$G$79, MATCH(A9, 'NILAI PREFERENSI & RANKING'!$K$4:$K$78, 0))} -> 1024 | H9: {=INDEX('DATA ALTERNATIF'!$H$5:$H$79, MATCH(A9, 'NILAI PREFERENSI & RANKING'!$K$4:$K$78, 0))} -> 3 | I9: {=INDEX('DATA ALTERNATIF'!$I$5:$I$79, MATCH(A9, 'NILAI PREFERENSI & RANKING'!$K$4:$K$78, 0))} -> 22199000 | J9: {=INDEX('NILAI PREFERENSI & RANKING'!$I$4:$I$78, MATCH(A9, 'NILAI PREFERENSI & RANKING'!$K$4:$K$78, 0))} -> 0.5375 | K9: Rekomendasi
A10: 6 | B10: {=INDEX('DATA ALTERNATIF'!$B$5:$B$79, MATCH(A10, 'NILAI PREFERENSI & RANKING'!$K$4:$K$78, 0))} -> A23 | C10: {=INDEX('DATA ALTERNATIF'!$C$5:$C$79, MATCH(A10, 'NILAI PREFERENSI & RANKING'!$K$4:$K$78, 0))} -> Acer Travelmate P414 Intel Core Ultra 7-155U | D10: {=INDEX('DATA ALTERNATIF'!$D$5:$D$79, MATCH(A10, 'NILAI PREFERENSI & RANKING'!$K$4:$K$78, 0))} -> Acer | E10: {=INDEX('DATA ALTERNATIF'!$E$5:$E$79, MATCH(A10, 'NILAI PREFERENSI & RANKING'!$K$4:$K$78, 0))} -> 43.75 | F10: {=INDEX('DATA ALTERNATIF'!$F$5:$F$79, MATCH(A10, 'NILAI PREFERENSI & RANKING'!$K$4:$K$78, 0))} -> 16 | G10: {=INDEX('DATA ALTERNATIF'!$G$5:$G$79, MATCH(A10, 'NILAI PREFERENSI & RANKING'!$K$4:$K$78, 0))} -> 1024 | H10: {=INDEX('DATA ALTERNATIF'!$H$5:$H$79, MATCH(A10, 'NILAI PREFERENSI & RANKING'!$K$4:$K$78, 0))} -> 3 | I10: {=INDEX('DATA ALTERNATIF'!$I$5:$I$79, MATCH(A10, 'NILAI PREFERENSI & RANKING'!$K$4:$K$78, 0))} -> 49284000 | J10: {=INDEX('NILAI PREFERENSI & RANKING'!$I$4:$I$78, MATCH(A10, 'NILAI PREFERENSI & RANKING'!$K$4:$K$78, 0))} -> 0.5375 | K10: Rekomendasi
A11: 7 | B11: {=INDEX('DATA ALTERNATIF'!$B$5:$B$79, MATCH(A11, 'NILAI PREFERENSI & RANKING'!$K$4:$K$78, 0))} -> A35 | C11: {=INDEX('DATA ALTERNATIF'!$C$5:$C$79, MATCH(A11, 'NILAI PREFERENSI & RANKING'!$K$4:$K$78, 0))} -> Acer Travelmate P414 i7-1260P | D11: {=INDEX('DATA ALTERNATIF'!$D$5:$D$79, MATCH(A11, 'NILAI PREFERENSI & RANKING'!$K$4:$K$78, 0))} -> Acer | E11: {=INDEX('DATA ALTERNATIF'!$E$5:$E$79, MATCH(A11, 'NILAI PREFERENSI & RANKING'!$K$4:$K$78, 0))} -> 43.75 | F11: {=INDEX('DATA ALTERNATIF'!$F$5:$F$79, MATCH(A11, 'NILAI PREFERENSI & RANKING'!$K$4:$K$78, 0))} -> 16 | G11: {=INDEX('DATA ALTERNATIF'!$G$5:$G$79, MATCH(A11, 'NILAI PREFERENSI & RANKING'!$K$4:$K$78, 0))} -> 1024 | H11: {=INDEX('DATA ALTERNATIF'!$H$5:$H$79, MATCH(A11, 'NILAI PREFERENSI & RANKING'!$K$4:$K$78, 0))} -> 3 | I11: {=INDEX('DATA ALTERNATIF'!$I$5:$I$79, MATCH(A11, 'NILAI PREFERENSI & RANKING'!$K$4:$K$78, 0))} -> 31635000 | J11: {=INDEX('NILAI PREFERENSI & RANKING'!$I$4:$I$78, MATCH(A11, 'NILAI PREFERENSI & RANKING'!$K$4:$K$78, 0))} -> 0.5375 | K11: Rekomendasi
A12: 8 | B12: {=INDEX('DATA ALTERNATIF'!$B$5:$B$79, MATCH(A12, 'NILAI PREFERENSI & RANKING'!$K$4:$K$78, 0))} -> A60 | C12: {=INDEX('DATA ALTERNATIF'!$C$5:$C$79, MATCH(A12, 'NILAI PREFERENSI & RANKING'!$K$4:$K$78, 0))} -> ASUS ExpertBook BG1409CVA | D12: {=INDEX('DATA ALTERNATIF'!$D$5:$D$79, MATCH(A12, 'NILAI PREFERENSI & RANKING'!$K$4:$K$78, 0))} -> Asus | E12: {=INDEX('DATA ALTERNATIF'!$E$5:$E$79, MATCH(A12, 'NILAI PREFERENSI & RANKING'!$K$4:$K$78, 0))} -> 44.59 | F12: {=INDEX('DATA ALTERNATIF'!$F$5:$F$79, MATCH(A12, 'NILAI PREFERENSI & RANKING'!$K$4:$K$78, 0))} -> 16 | G12: {=INDEX('DATA ALTERNATIF'!$G$5:$G$79, MATCH(A12, 'NILAI PREFERENSI & RANKING'!$K$4:$K$78, 0))} -> 1024 | H12: {=INDEX('DATA ALTERNATIF'!$H$5:$H$79, MATCH(A12, 'NILAI PREFERENSI & RANKING'!$K$4:$K$78, 0))} -> 2 | I12: {=INDEX('DATA ALTERNATIF'!$I$5:$I$79, MATCH(A12, 'NILAI PREFERENSI & RANKING'!$K$4:$K$78, 0))} -> 18426000 | J12: {=INDEX('NILAI PREFERENSI & RANKING'!$I$4:$I$78, MATCH(A12, 'NILAI PREFERENSI & RANKING'!$K$4:$K$78, 0))} -> 0.5 | K12: Rekomendasi
A13: 9 | B13: {=INDEX('DATA ALTERNATIF'!$B$5:$B$79, MATCH(A13, 'NILAI PREFERENSI & RANKING'!$K$4:$K$78, 0))} -> A52 | C13: {=INDEX('DATA ALTERNATIF'!$C$5:$C$79, MATCH(A13, 'NILAI PREFERENSI & RANKING'!$K$4:$K$78, 0))} -> Advan Workplus 12600H | D13: {=INDEX('DATA ALTERNATIF'!$D$5:$D$79, MATCH(A13, 'NILAI PREFERENSI & RANKING'!$K$4:$K$78, 0))} -> Advan | E13: {=INDEX('DATA ALTERNATIF'!$E$5:$E$79, MATCH(A13, 'NILAI PREFERENSI & RANKING'!$K$4:$K$78, 0))} -> 25.04 | F13: {=INDEX('DATA ALTERNATIF'!$F$5:$F$79, MATCH(A13, 'NILAI PREFERENSI & RANKING'!$K$4:$K$78, 0))} -> 24 | G13: {=INDEX('DATA ALTERNATIF'!$G$5:$G$79, MATCH(A13, 'NILAI PREFERENSI & RANKING'!$K$4:$K$78, 0))} -> 512 | H13: {=INDEX('DATA ALTERNATIF'!$H$5:$H$79, MATCH(A13, 'NILAI PREFERENSI & RANKING'!$K$4:$K$78, 0))} -> 1 | I13: {=INDEX('DATA ALTERNATIF'!$I$5:$I$79, MATCH(A13, 'NILAI PREFERENSI & RANKING'!$K$4:$K$78, 0))} -> 11100000 | J13: {=INDEX('NILAI PREFERENSI & RANKING'!$I$4:$I$78, MATCH(A13, 'NILAI PREFERENSI & RANKING'!$K$4:$K$78, 0))} -> 0.484 | K13: Rekomendasi
A14: 10 | B14: {=INDEX('DATA ALTERNATIF'!$B$5:$B$79, MATCH(A14, 'NILAI PREFERENSI & RANKING'!$K$4:$K$78, 0))} -> A57 | C14: {=INDEX('DATA ALTERNATIF'!$C$5:$C$79, MATCH(A14, 'NILAI PREFERENSI & RANKING'!$K$4:$K$78, 0))} -> ASUS ExpertBook BG1408CVA | D14: {=INDEX('DATA ALTERNATIF'!$D$5:$D$79, MATCH(A14, 'NILAI PREFERENSI & RANKING'!$K$4:$K$78, 0))} -> ASUS | E14: {=INDEX('DATA ALTERNATIF'!$E$5:$E$79, MATCH(A14, 'NILAI PREFERENSI & RANKING'!$K$4:$K$78, 0))} -> 44.87 | F14: {=INDEX('DATA ALTERNATIF'!$F$5:$F$79, MATCH(A14, 'NILAI PREFERENSI & RANKING'!$K$4:$K$78, 0))} -> 16 | G14: {=INDEX('DATA ALTERNATIF'!$G$5:$G$79, MATCH(A14, 'NILAI PREFERENSI & RANKING'!$K$4:$K$78, 0))} -> 512 | H14: {=INDEX('DATA ALTERNATIF'!$H$5:$H$79, MATCH(A14, 'NILAI PREFERENSI & RANKING'!$K$4:$K$78, 0))} -> 3 | I14: {=INDEX('DATA ALTERNATIF'!$I$5:$I$79, MATCH(A14, 'NILAI PREFERENSI & RANKING'!$K$4:$K$78, 0))} -> 16400000 | J14: {=INDEX('NILAI PREFERENSI & RANKING'!$I$4:$I$78, MATCH(A14, 'NILAI PREFERENSI & RANKING'!$K$4:$K$78, 0))} -> 0.4798 | K14: Rekomendasi
A15: 11 | B15: {=INDEX('DATA ALTERNATIF'!$B$5:$B$79, MATCH(A15, 'NILAI PREFERENSI & RANKING'!$K$4:$K$78, 0))} -> A20 | C15: {=INDEX('DATA ALTERNATIF'!$C$5:$C$79, MATCH(A15, 'NILAI PREFERENSI & RANKING'!$K$4:$K$78, 0))} -> Acer TravelMate P414 Core-i5-1240P | D15: {=INDEX('DATA ALTERNATIF'!$D$5:$D$79, MATCH(A15, 'NILAI PREFERENSI & RANKING'!$K$4:$K$78, 0))} -> Acer | E15: {=INDEX('DATA ALTERNATIF'!$E$5:$E$79, MATCH(A15, 'NILAI PREFERENSI & RANKING'!$K$4:$K$78, 0))} -> 44.67 | F15: {=INDEX('DATA ALTERNATIF'!$F$5:$F$79, MATCH(A15, 'NILAI PREFERENSI & RANKING'!$K$4:$K$78, 0))} -> 16 | G15: {=INDEX('DATA ALTERNATIF'!$G$5:$G$79, MATCH(A15, 'NILAI PREFERENSI & RANKING'!$K$4:$K$78, 0))} -> 512 | H15: {=INDEX('DATA ALTERNATIF'!$H$5:$H$79, MATCH(A15, 'NILAI PREFERENSI & RANKING'!$K$4:$K$78, 0))} -> 3 | I15: {=INDEX('DATA ALTERNATIF'!$I$5:$I$79, MATCH(A15, 'NILAI PREFERENSI & RANKING'!$K$4:$K$78, 0))} -> 22089000 | J15: {=INDEX('NILAI PREFERENSI & RANKING'!$I$4:$I$78, MATCH(A15, 'NILAI PREFERENSI & RANKING'!$K$4:$K$78, 0))} -> 0.4715 | K15: Memenuhi syarat
A16: 12 | B16: {=INDEX('DATA ALTERNATIF'!$B$5:$B$79, MATCH(A16, 'NILAI PREFERENSI & RANKING'!$K$4:$K$78, 0))} -> A49 | C16: {=INDEX('DATA ALTERNATIF'!$C$5:$C$79, MATCH(A16, 'NILAI PREFERENSI & RANKING'!$K$4:$K$78, 0))} -> Advan Workplus R5 | D16: {=INDEX('DATA ALTERNATIF'!$D$5:$D$79, MATCH(A16, 'NILAI PREFERENSI & RANKING'!$K$4:$K$78, 0))} -> Advan | E16: {=INDEX('DATA ALTERNATIF'!$E$5:$E$79, MATCH(A16, 'NILAI PREFERENSI & RANKING'!$K$4:$K$78, 0))} -> 39.29 | F16: {=INDEX('DATA ALTERNATIF'!$F$5:$F$79, MATCH(A16, 'NILAI PREFERENSI & RANKING'!$K$4:$K$78, 0))} -> 16 | G16: {=INDEX('DATA ALTERNATIF'!$G$5:$G$79, MATCH(A16, 'NILAI PREFERENSI & RANKING'!$K$4:$K$78, 0))} -> 512 | H16: {=INDEX('DATA ALTERNATIF'!$H$5:$H$79, MATCH(A16, 'NILAI PREFERENSI & RANKING'!$K$4:$K$78, 0))} -> 1 | I16: {=INDEX('DATA ALTERNATIF'!$I$5:$I$79, MATCH(A16, 'NILAI PREFERENSI & RANKING'!$K$4:$K$78, 0))} -> 8000000 | J16: {=INDEX('NILAI PREFERENSI & RANKING'!$I$4:$I$78, MATCH(A16, 'NILAI PREFERENSI & RANKING'!$K$4:$K$78, 0))} -> 0.4715 | K16: Memenuhi syarat
A17: 13 | B17: {=INDEX('DATA ALTERNATIF'!$B$5:$B$79, MATCH(A17, 'NILAI PREFERENSI & RANKING'!$K$4:$K$78, 0))} -> A22 | C17: {=INDEX('DATA ALTERNATIF'!$C$5:$C$79, MATCH(A17, 'NILAI PREFERENSI & RANKING'!$K$4:$K$78, 0))} -> Acer Travelmate P414 i7-1260P 106986 | D17: {=INDEX('DATA ALTERNATIF'!$D$5:$D$79, MATCH(A17, 'NILAI PREFERENSI & RANKING'!$K$4:$K$78, 0))} -> Acer | E17: {=INDEX('DATA ALTERNATIF'!$E$5:$E$79, MATCH(A17, 'NILAI PREFERENSI & RANKING'!$K$4:$K$78, 0))} -> 28.88 | F17: {=INDEX('DATA ALTERNATIF'!$F$5:$F$79, MATCH(A17, 'NILAI PREFERENSI & RANKING'!$K$4:$K$78, 0))} -> 16 | G17: {=INDEX('DATA ALTERNATIF'!$G$5:$G$79, MATCH(A17, 'NILAI PREFERENSI & RANKING'!$K$4:$K$78, 0))} -> 1000 | H17: {=INDEX('DATA ALTERNATIF'!$H$5:$H$79, MATCH(A17, 'NILAI PREFERENSI & RANKING'!$K$4:$K$78, 0))} -> 1 | I17: {=INDEX('DATA ALTERNATIF'!$I$5:$I$79, MATCH(A17, 'NILAI PREFERENSI & RANKING'!$K$4:$K$78, 0))} -> 38694600 | J17: {=INDEX('NILAI PREFERENSI & RANKING'!$I$4:$I$78, MATCH(A17, 'NILAI PREFERENSI & RANKING'!$K$4:$K$78, 0))} -> 0.4625 | K17: Memenuhi syarat
